Workbook

Sheet JAN
A1: January | B1: Monthly Regular Bills | C1: 46023 | D1: =C1+1 -> 46024 | E1: =D1+1 -> 46025 | F1: =E1+1 -> 46026 | G1: =F1+1 -> 46027 | H1: =G1+1 -> 46028 | I1: =H1+1 -> 46029 | J1: =I1+1 -> 46030 | K1: =J1+1 -> 46031 | ... AG1: =AF1+1 -> 46053 | AH1: TOTALS | AI1: SPENDING PLAN | AJ1: DIFFERENCE
A2: INCOME
A3: Main Job | AH3: =sum(B3:AG3) -> 0 | AI3: ='TOTALS&AVERAGES'!N3 | AJ3: =AI3-AH3 -> 0
A4: B Job | AH4: =sum(B4:AG4) -> 0 | AI4: ='TOTALS&AVERAGES'!N4 | AJ4: =AI4-AH4 -> 0
A5: Bonuses | AH5: =sum(B5:AG5) -> 0 | AI5: ='TOTALS&AVERAGES'!N5 | AJ5: =AI5-AH5 -> 0
A6: Gifts/Discounts | AH6: =sum(B6:AG6) -> 0 | AI6: ='TOTALS&AVERAGES'!N6 | AJ6: =AI6-AH6 -> 0
A7: Reimbursement | AH7: =sum(B7:AG7) -> 0 | AI7: ='TOTALS&AVERAGES'!N7 | AJ7: =AI7-AH7 -> 0
A8: Government Assistance | AH8: =sum(B8:AG8) -> 0 | AI8: ='TOTALS&AVERAGES'!N8 | AJ8: =AI8-AH8 -> 0
A9: Side Hustles | AH9: =sum(B9:AG9) -> 0 | AI9: ='TOTALS&AVERAGES'!N9 | AJ9: =AI9-AH9 -> 0
A10: Interest/Rewards | AH10: =sum(B10:AG10) -> 0 | AI10: ='TOTALS&AVERAGES'!N10 | AJ10: =AI10-AH10 -> 0
A11: VA Benefits | AH11: =sum(B11:AG11) -> 0 | AI11: ='TOTALS&AVERAGES'!N11 | AJ11: =AI11-AH11 -> 0
A12: Asset Cash Out | AH12: =sum(B12:AG12) -> 0 | AI12: ='TOTALS&AVERAGES'!N12 | AJ12: =AI12-AH12 -> 0
A13: Fed Tax Refund | AH13: =sum(B13:AG13) -> 0 | AI13: ='TOTALS&AVERAGES'!N13 | AJ13: =AI13-AH13 -> 0
A14: State Tax Refund | AH14: =sum(B14:AG14) -> 0 | AI14: ='TOTALS&AVERAGES'!N14 | AJ14: =AI14-AH14 -> 0
A15: TOTAL INCOME BEFORE TAXES | B15: =SUM(C3:AG14) -> 0 | C15: =SUM(C3:C14) -> 0 | D15: =SUM(D3:D14) -> 0 | E15: =SUM(E3:E14) -> 0 | F15: =SUM(F3:F14) -> 0 | G15: =SUM(G3:G14) -> 0 | H15: =SUM(H3:H14) -> 0 | I15: =SUM(I3:I14) -> 0 | J15: =SUM(J3:J14) -> 0 | ... AJ15: =SUM(AJ3:AJ14) -> 0
A16: EXPENSES BY D.A. CATEGORIES | B16: MONTHLY REGULAR BILLS
A17: SPIRITUAL | B17: =SUM(B18:B26) -> 0 | C17: =SUM(C18:C26) -> 0 | D17: =SUM(D18:D26) -> 0 | E17: =SUM(E18:E26) -> 0 | F17: =SUM(F18:F26) -> 0 | G17: =SUM(G18:G26) -> 0 | H17: =SUM(H18:H26) -> 0 | I17: =SUM(I18:I26) -> 0 | ... AJ17: =SUM(AJ18:AJ26) -> 0
A18: Tithing/Church Donation | AH18: =sum(B18:AG18) -> 0 | AI18: ='TOTALS&AVERAGES'!N18 | AJ18: =AI18-AH18 -> 0
A19: Books | AH19: =sum(B19:AG19) -> 0 | AI19: ='TOTALS&AVERAGES'!N19 | AJ19: =AI19-AH19 -> 0
A20: Charity | AH20: =sum(B20:AG20) -> 0 | AI20: ='TOTALS&AVERAGES'!N20 | AJ20: =AI20-AH20 -> 0
A21: Workshops | AH21: =sum(B21:AG21) -> 0 | AI21: ='TOTALS&AVERAGES'!N21 | AJ21: =AI21-AH21 -> 0
A22: Generosity | AH22: =sum(B22:AG22) -> 0 | AI22: ='TOTALS&AVERAGES'!N22 | AJ22: =AI22-AH22 -> 0
A23: Retreats / Seminars | AH23: =sum(B23:AG23) -> 0 | AI23: ='TOTALS&AVERAGES'!N23 | AJ23: =AI23-AH23 -> 0
A24: 7TH TRADITION / FELLOWSHIP/ PRG | AH24: =sum(B24:AG24) -> 0 | AI24: ='TOTALS&AVERAGES'!N24 | AJ24: =AI24-AH24 -> 0
A25: Conferences | AH25: =sum(B25:AG25) -> 0 | AI25: ='TOTALS&AVERAGES'!N25 | AJ25: =AI25-AH25 -> 0
A26: Career Investment | AH26: =sum(B26:AG26) -> 0 | AI26: ='TOTALS&AVERAGES'!N26 | AJ26: =AI26-AH26 -> 0
A27: Needs | B27: =SUM(B28:B43) -> 0 | C27: =SUM(C28:C43) -> 0 | D27: =SUM(D28:D43) -> 0 | E27: =SUM(E28:E43) -> 0 | F27: =SUM(F28:F43) -> 0 | G27: =SUM(G28:G43) -> 0 | H27: =SUM(H28:H43) -> 0 | I27: =SUM(I28:I43) -> 0 | ... AJ27: =SUM(AJ28:AJ43) -> 0
A28: Groceries | AH28: =sum(B28:AG28) -> 0 | AI28: ='TOTALS&AVERAGES'!N28 | AJ28: =AI28-AH28 -> 0
A29: Rent/Mortage | B29: 1st | AH29: =sum(B29:AG29) -> 0 | AI29: ='TOTALS&AVERAGES'!N29 | AJ29: =AI29-AH29 -> 0
A30: Cell Phone | B30: 20th | AH30: =sum(B30:AG30) -> 0 | AI30: ='TOTALS&AVERAGES'!N30 | AJ30: =AI30-AH30 -> 0
A31: Laundry/Cleaners | B31: * | AH31: =sum(B31:AG31) -> 0 | AI31: ='TOTALS&AVERAGES'!N31 | AJ31: =AI31-AH31 -> 0
A32: Car Fuel | B32: * | AH32: =sum(B32:AG32) -> 0 | AI32: ='TOTALS&AVERAGES'!N32 | AJ32: =AI32-AH32 -> 0
A33: Car Insurance | B33: * | AH33: =sum(B33:AG33) -> 0 | AI33: ='TOTALS&AVERAGES'!N33 | AJ33: =AI33-AH33 -> 0
A34: Home Items | B34: * | AH34: =sum(B34:AG34) -> 0 | AI34: ='TOTALS&AVERAGES'!N34 | AJ34: =AI34-AH34 -> 0
A35: Internet | AH35: =sum(B35:AG35) -> 0 | AI35: ='TOTALS&AVERAGES'!N35 | AJ35: =AI35-AH35 -> 0
A36: Electricity | B36: * | AH36: =sum(B36:AG36) -> 0 | AI36: ='TOTALS&AVERAGES'!N36 | AJ36: =AI36-AH36 -> 0
A37: Card Fees | AH37: =sum(B37:AG37) -> 0 | AI37: ='TOTALS&AVERAGES'!N37 | AJ37: =AI37-AH37 -> 0
A38: Moving | AH38: =sum(B38:AG38) -> 0 | AI38: ='TOTALS&AVERAGES'!N38 | AJ38: =AI38-AH38 -> 0
A39: Toiletries | B39: * | AH39: =sum(B39:AG39) -> 0 | AI39: ='TOTALS&AVERAGES'!N39 | AJ39: =AI39-AH39 -> 0
A40: Storage | B40: * | AH40: =sum(B40:AG40) -> 0 | AI40: ='TOTALS&AVERAGES'!N40 | AJ40: =AI40-AH40 -> 0
...

Sheet FEB
A1: FEBRUARY | B1: Monthly Regular Bills | C1: 46054 | D1: =C1+1 -> 46055 | E1: =D1+1 -> 46056 | F1: =E1+1 -> 46057 | G1: =F1+1 -> 46058 | H1: =G1+1 -> 46059 | I1: =H1+1 -> 46060 | J1: =I1+1 -> 46061 | K1: =J1+1 -> 46062 | ... AD1: =AC1+1 -> 46081 | AE1: TOTALS | AF1: SPENDING PLAN | AG1: DIFFERENCE
A2: INCOME
A3: =JAN!A3 -> Main Job | AE3: =sum(B3:AD3) -> 0 | AF3: ='TOTALS&AVERAGES'!N3 | AG3: =AF3-AE3 -> 0
A4: =JAN!A4 -> B Job | AE4: =sum(B4:AD4) -> 0 | AF4: ='TOTALS&AVERAGES'!N4 | AG4: =AF4-AE4 -> 0
A5: =JAN!A5 -> Bonuses | AE5: =sum(B5:AD5) -> 0 | AF5: ='TOTALS&AVERAGES'!N5 | AG5: =AF5-AE5 -> 0
A6: =JAN!A6 -> Gifts/Discounts | AE6: =sum(B6:AD6) -> 0 | AF6: ='TOTALS&AVERAGES'!N6 | AG6: =AF6-AE6 -> 0
A7: =JAN!A7 -> Reimbursement | AE7: =sum(B7:AD7) -> 0 | AF7: ='TOTALS&AVERAGES'!N7 | AG7: =AF7-AE7 -> 0
A8: =JAN!A8 -> Government Assistance | AE8: =sum(B8:AD8) -> 0 | AF8: ='TOTALS&AVERAGES'!N8 | AG8: =AF8-AE8 -> 0
A9: =JAN!A9 -> Side Hustles | AE9: =sum(B9:AD9) -> 0 | AF9: ='TOTALS&AVERAGES'!N9 | AG9: =AF9-AE9 -> 0
A10: =JAN!A10 -> Interest/Rewards | AE10: =sum(B10:AD10) -> 0 | AF10: ='TOTALS&AVERAGES'!N10 | AG10: =AF10-AE10 -> 0
A11: =JAN!A11 -> VA Benefits | AE11: =sum(B11:AD11) -> 0 | AF11: ='TOTALS&AVERAGES'!N11 | AG11: =AF11-AE11 -> 0
A12: =JAN!A12 -> Asset Cash Out | AE12: =sum(B12:AD12) -> 0 | AF12: ='TOTALS&AVERAGES'!N12 | AG12: =AF12-AE12 -> 0
A13: =JAN!A13 -> Fed Tax Refund | AE13: =sum(B13:AD13) -> 0 | AF13: ='TOTALS&AVERAGES'!N13 | AG13: =AF13-AE13 -> 0
A14: =JAN!A14 -> State Tax Refund | AE14: =sum(B14:AD14) -> 0 | AF14: ='TOTALS&AVERAGES'!N14 | AG14: =AF14-AE14 -> 0
A15: TOTAL INCOME BEFORE TAXES | B15: =SUM(C3:AE14) -> 0 | C15: =SUM(C3:C14) -> 0 | D15: =SUM(D3:D14) -> 0 | E15: =SUM(E3:E14) -> 0 | F15: =SUM(F3:F14) -> 0 | G15: =SUM(G3:G14) -> 0 | H15: =SUM(H3:H14) -> 0 | I15: =SUM(I3:I14) -> 0 | J15: =SUM(J3:J14) -> 0 | ... AG15: =SUM(AG3:AG14) -> 0
A16: EXPENSES BY D.A. CATEGORIES | B16: MONTHLY REGULAR BILLS
A17: 1 - SPIRITUAL | B17: =SUM(B18:B26) -> 0 | C17: =SUM(C18:C26) -> 0 | D17: =SUM(D18:D26) -> 0 | E17: =SUM(E18:E26) -> 0 | F17: =SUM(F18:F26) -> 0 | G17: =SUM(G18:G26) -> 0 | H17: =SUM(H18:H26) -> 0 | I17: =SUM(I18:I26) -> 0 | ... AG17: =SUM(AG18:AG26) -> 0
A18: =JAN!A18 -> Tithing/Church Donation | AE18: =sum(B18:AD18) -> 0 | AF18: ='TOTALS&AVERAGES'!N18 | AG18: =AF18-AE18 -> 0
A19: =JAN!A19 -> Books | AE19: =sum(B19:AD19) -> 0 | AF19: ='TOTALS&AVERAGES'!N19 | AG19: =AF19-AE19 -> 0
A20: =JAN!A20 -> Charity | AE20: =sum(B20:AD20) -> 0 | AF20: ='TOTALS&AVERAGES'!N20 | AG20: =AF20-AE20 -> 0
A21: =JAN!A21 -> Workshops | AE21: =sum(B21:AD21) -> 0 | AF21: ='TOTALS&AVERAGES'!N21 | AG21: =AF21-AE21 -> 0
A22: =JAN!A22 -> Generosity | AE22: =sum(B22:AD22) -> 0 | AF22: ='TOTALS&AVERAGES'!N22 | AG22: =AF22-AE22 -> 0
A23: =JAN!A23 -> Retreats / Seminars | AE23: =sum(B23:AD23) -> 0 | AF23: ='TOTALS&AVERAGES'!N23 | AG23: =AF23-AE23 -> 0
A24: =JAN!A24 -> 7TH TRADITION / FELLOWSHIP/ PRG | AE24: =sum(B24:AD24) -> 0 | AF24: ='TOTALS&AVERAGES'!N24 | AG24: =AF24-AE24 -> 0
A25: =JAN!A25 -> Conferences | AE25: =sum(B25:AD25) -> 0 | AF25: ='TOTALS&AVERAGES'!N25 | AG25: =AF25-AE25 -> 0
A26: =JAN!A26 -> Career Investment | AE26: =sum(B26:AD26) -> 0 | AF26: ='TOTALS&AVERAGES'!N26 | AG26: =AF26-AE26 -> 0
A27: =JAN!A27 -> Needs | B27: =SUM(B28:B43) -> 0 | C27: =SUM(C28:C43) -> 0 | D27: =SUM(D28:D43) -> 0 | E27: =SUM(E28:E43) -> 0 | F27: =SUM(F28:F43) -> 0 | G27: =SUM(G28:G43) -> 0 | H27: =SUM(H28:H43) -> 0 | I27: =SUM(I28:I43) -> 0 | ... AG27: =SUM(AG28:AG43) -> 0
A28: =JAN!A28 -> Groceries | AE28: =sum(B28:AD28) -> 0 | AF28: ='TOTALS&AVERAGES'!N28 | AG28: =AF28-AE28 -> 0
A29: =JAN!A29 -> Rent/Mortage | B29: * | AE29: =sum(B29:AD29) -> 0 | AF29: ='TOTALS&AVERAGES'!N29 | AG29: =AF29-AE29 -> 0
A30: =JAN!A30 -> Cell Phone | B30: * | AE30: =sum(B30:AD30) -> 0 | AF30: ='TOTALS&AVERAGES'!N30 | AG30: =AF30-AE30 -> 0
A31: =JAN!A31 -> Laundry/Cleaners | B31: * | AE31: =sum(B31:AD31) -> 0 | AF31: ='TOTALS&AVERAGES'!N31 | AG31: =AF31-AE31 -> 0
A32: =JAN!A32 -> Car Fuel | B32: * | AE32: =sum(B32:AD32) -> 0 | AF32: ='TOTALS&AVERAGES'!N32 | AG32: =AF32-AE32 -> 0
A33: =JAN!A33 -> Car Insurance | B33: * | AE33: =sum(B33:AD33) -> 0 | AF33: ='TOTALS&AVERAGES'!N33 | AG33: =AF33-AE33 -> 0
A34: =JAN!A34 -> Home Items | B34: * | AE34: =sum(B34:AD34) -> 0 | AF34: ='TOTALS&AVERAGES'!N34 | AG34: =AF34-AE34 -> 0
A35: =JAN!A35 -> Internet | AE35: =sum(B35:AD35) -> 0 | AF35: ='TOTALS&AVERAGES'!N35 | AG35: =AF35-AE35 -> 0
A36: =JAN!A36 -> Electricity | B36: * | AE36: =sum(B36:AD36) -> 0 | AF36: ='TOTALS&AVERAGES'!N36 | AG36: =AF36-AE36 -> 0
A37: =JAN!A37 -> Card Fees | AE37: =sum(B37:AD37) -> 0 | AF37: ='TOTALS&AVERAGES'!N37 | AG37: =AF37-AE37 -> 0
A38: =JAN!A38 -> Moving | AE38: =sum(B38:AD38) -> 0 | AF38: ='TOTALS&AVERAGES'!N38 | AG38: =AF38-AE38 -> 0
A39: =JAN!A39 -> Toiletries | B39: * | AE39: =sum(B39:AD39) -> 0 | AF39: ='TOTALS&AVERAGES'!N39 | AG39: =AF39-AE39 -> 0
A40: =JAN!A40 -> Storage | B40: * | AE40: =sum(B40:AD40) -> 0 | AF40: ='TOTALS&AVERAGES'!N40 | AG40: =AF40-AE40 -> 0
...

Sheet MAR
A1: MARCH | B1: Monthly Regular Bills | C1: 46082 | D1: =C1+1 -> 46083 | E1: =D1+1 -> 46084 | F1: =E1+1 -> 46085 | G1: =F1+1 -> 46086 | H1: =G1+1 -> 46087 | I1: =H1+1 -> 46088 | J1: =I1+1 -> 46089 | K1: =J1+1 -> 46090 | ... AG1: =AF1+1 -> 46112 | AH1: TOTALS | AI1: SPENDING PLAN | AJ1: DIFFERENCE
A2: INCOME
A3: =JAN!A3 -> Main Job | AH3: =sum(B3:AF3) -> 0 | AI3: ='TOTALS&AVERAGES'!N3 | AJ3: =AI3-AH3 -> 0
A4: =JAN!A4 -> B Job | AH4: =sum(B4:AF4) -> 0 | AI4: ='TOTALS&AVERAGES'!N4 | AJ4: =AI4-AH4 -> 0
A5: =JAN!A5 -> Bonuses | AH5: =sum(B5:AF5) -> 0 | AI5: ='TOTALS&AVERAGES'!N5 | AJ5: =AI5-AH5 -> 0
A6: =JAN!A6 -> Gifts/Discounts | AH6: =sum(B6:AF6) -> 0 | AI6: ='TOTALS&AVERAGES'!N6 | AJ6: =AI6-AH6 -> 0
A7: =JAN!A7 -> Reimbursement | AH7: =sum(B7:AF7) -> 0 | AI7: ='TOTALS&AVERAGES'!N7 | AJ7: =AI7-AH7 -> 0
A8: =JAN!A8 -> Government Assistance | AH8: =sum(B8:AF8) -> 0 | AI8: ='TOTALS&AVERAGES'!N8 | AJ8: =AI8-AH8 -> 0
A9: =JAN!A9 -> Side Hustles | AH9: =sum(B9:AF9) -> 0 | AI9: ='TOTALS&AVERAGES'!N9 | AJ9: =AI9-AH9 -> 0
A10: =JAN!A10 -> Interest/Rewards | AH10: =sum(B10:AG10) -> 0 | AI10: ='TOTALS&AVERAGES'!N10 | AJ10: =AI10-AH10 -> 0
A11: =JAN!A11 -> VA Benefits | AH11: =sum(B11:AF11) -> 0 | AI11: ='TOTALS&AVERAGES'!N11 | AJ11: =AI11-AH11 -> 0
A12: =JAN!A12 -> Asset Cash Out | AH12: =sum(B12:AF12) -> 0 | AI12: ='TOTALS&AVERAGES'!N12 | AJ12: =AI12-AH12 -> 0
A13: =JAN!A13 -> Fed Tax Refund | AH13: =sum(B13:AF13) -> 0 | AI13: ='TOTALS&AVERAGES'!N13 | AJ13: =AI13-AH13 -> 0
A14: =JAN!A14 -> State Tax Refund | AH14: =sum(B14:AF14) -> 0 | AI14: ='TOTALS&AVERAGES'!N14 | AJ14: =AI14-AH14 -> 0
A15: TOTAL INCOME BEFORE TAXES | B15: =SUM(C3:AH14) -> 0 | C15: =SUM(C3:C14) -> 0 | D15: =SUM(D3:D14) -> 0 | E15: =SUM(E3:E14) -> 0 | F15: =SUM(F3:F14) -> 0 | G15: =SUM(G3:G14) -> 0 | H15: =SUM(H3:H14) -> 0 | I15: =SUM(I3:I14) -> 0 | J15: =SUM(J3:J14) -> 0 | ... AJ15: =SUM(AJ3:AJ14) -> 0
A16: EXPENSES BY D.A. CATEGORIES | B16: MONTHLY REGULAR BILLS
A17: 1 - SPIRITUAL | B17: =SUM(B18:B26) -> 0 | C17: =SUM(C18:C26) -> 0 | D17: =SUM(D18:D26) -> 0 | E17: =SUM(E18:E26) -> 0 | F17: =SUM(F18:F26) -> 0 | G17: =SUM(G18:G26) -> 0 | H17: =SUM(H18:H26) -> 0 | I17: =SUM(I18:I26) -> 0 | ... AJ17: =SUM(AJ18:AJ26) -> 0
A18: =JAN!A18 -> Tithing/Church Donation | AH18: =sum(B18:AF18) -> 0 | AI18: ='TOTALS&AVERAGES'!N18 | AJ18: =AI18-AH18 -> 0
A19: =JAN!A19 -> Books | AH19: =sum(B19:AF19) -> 0 | AI19: ='TOTALS&AVERAGES'!N19 | AJ19: =AI19-AH19 -> 0
A20: =JAN!A20 -> Charity | AH20: =sum(B20:AF20) -> 0 | AI20: ='TOTALS&AVERAGES'!N20 | AJ20: =AI20-AH20 -> 0
A21: =JAN!A21 -> Workshops | AH21: =sum(B21:AF21) -> 0 | AI21: ='TOTALS&AVERAGES'!N21 | AJ21: =AI21-AH21 -> 0
A22: =JAN!A22 -> Generosity | AH22: =sum(B22:AF22) -> 0 | AI22: ='TOTALS&AVERAGES'!N22 | AJ22: =AI22-AH22 -> 0
A23: =JAN!A23 -> Retreats / Seminars | AH23: =sum(B23:AF23) -> 0 | AI23: ='TOTALS&AVERAGES'!N23 | AJ23: =AI23-AH23 -> 0
A24: =JAN!A24 -> 7TH TRADITION / FELLOWSHIP/ PRG | AH24: =sum(B24:AF24) -> 0 | AI24: ='TOTALS&AVERAGES'!N24 | AJ24: =AI24-AH24 -> 0
A25: =JAN!A25 -> Conferences | AH25: =sum(B25:AF25) -> 0 | AI25: ='TOTALS&AVERAGES'!N25 | AJ25: =AI25-AH25 -> 0
A26: =JAN!A26 -> Career Investment | AH26: =sum(B26:AF26) -> 0 | AI26: ='TOTALS&AVERAGES'!N26 | AJ26: =AI26-AH26 -> 0
A27: =JAN!A27 -> Needs | B27: =SUM(B28:B43) -> 0 | C27: =SUM(C28:C43) -> 0 | D27: =SUM(D28:D43) -> 0 | E27: =SUM(E28:E43) -> 0 | F27: =SUM(F28:F43) -> 0 | G27: =SUM(G28:G43) -> 0 | H27: =SUM(H28:H43) -> 0 | I27: =SUM(I28:I43) -> 0 | ... AJ27: =SUM(AJ28:AJ43) -> 0
A28: =JAN!A28 -> Groceries | AH28: =sum(B28:AF28) -> 0 | AI28: ='TOTALS&AVERAGES'!N28 | AJ28: =AI28-AH28 -> 0
A29: =JAN!A29 -> Rent/Mortage | B29: * | AH29: =sum(B29:AF29) -> 0 | AI29: ='TOTALS&AVERAGES'!N29 | AJ29: =AI29-AH29 -> 0
A30: =JAN!A30 -> Cell Phone | B30: * | AH30: =sum(B30:AF30) -> 0 | AI30: ='TOTALS&AVERAGES'!N30 | AJ30: =AI30-AH30 -> 0
A31: =JAN!A31 -> Laundry/Cleaners | B31: * | AH31: =sum(B31:AF31) -> 0 | AI31: ='TOTALS&AVERAGES'!N31 | AJ31: =AI31-AH31 -> 0
A32: =JAN!A32 -> Car Fuel | B32: * | AH32: =sum(B32:AF32) -> 0 | AI32: ='TOTALS&AVERAGES'!N32 | AJ32: =AI32-AH32 -> 0
A33: =JAN!A33 -> Car Insurance | B33: * | AH33: =sum(B33:AF33) -> 0 | AI33: ='TOTALS&AVERAGES'!N33 | AJ33: =AI33-AH33 -> 0
A34: =JAN!A34 -> Home Items | B34: * | AH34: =sum(B34:AF34) -> 0 | AI34: ='TOTALS&AVERAGES'!N34 | AJ34: =AI34-AH34 -> 0
A35: =JAN!A35 -> Internet | AH35: =sum(B35:AF35) -> 0 | AI35: ='TOTALS&AVERAGES'!N35 | AJ35: =AI35-AH35 -> 0
A36: =JAN!A36 -> Electricity | B36: * | AH36: =sum(B36:AF36) -> 0 | AI36: ='TOTALS&AVERAGES'!N36 | AJ36: =AI36-AH36 -> 0
A37: =JAN!A37 -> Card Fees | AH37: =sum(B37:AF37) -> 0 | AI37: ='TOTALS&AVERAGES'!N37 | AJ37: =AI37-AH37 -> 0
A38: =JAN!A38 -> Moving | AH38: =sum(B38:AF38) -> 0 | AI38: ='TOTALS&AVERAGES'!N38 | AJ38: =AI38-AH38 -> 0
A39: =JAN!A39 -> Toiletries | B39: * | AH39: =sum(B39:AF39) -> 0 | AI39: ='TOTALS&AVERAGES'!N39 | AJ39: =AI39-AH39 -> 0
A40: =JAN!A40 -> Storage | B40: * | AH40: =sum(B40:AF40) -> 0 | AI40: ='TOTALS&AVERAGES'!N40 | AJ40: =AI40-AH40 -> 0
...

Sheet APR
A1: APRIL | B1: Monthly Regular Bills | C1: 46113 | D1: =C1+1 -> 46114 | E1: =D1+1 -> 46115 | F1: =E1+1 -> 46116 | G1: =F1+1 -> 46117 | H1: =G1+1 -> 46118 | I1: =H1+1 -> 46119 | J1: =I1+1 -> 46120 | K1: =J1+1 -> 46121 | ... AG1: =AF1+1 -> 46143 | AH1: TOTALS | AI1: SPENDING PLAN | AJ1: DIFFERENCE
A2: INCOME
A3: =JAN!A3 -> Main Job | AH3: =sum(B3:AF3) -> 0 | AI3: ='TOTALS&AVERAGES'!N3 | AJ3: =AI3-AH3 -> 0
A4: =JAN!A4 -> B Job | AH4: =sum(B4:AF4) -> 0 | AI4: ='TOTALS&AVERAGES'!N4 | AJ4: =AI4-AH4 -> 0
A5: =JAN!A5 -> Bonuses | AH5: =sum(B5:AF5) -> 0 | AI5: ='TOTALS&AVERAGES'!N5 | AJ5: =AI5-AH5 -> 0
A6: =JAN!A6 -> Gifts/Discounts | AH6: =sum(B6:AF6) -> 0 | AI6: ='TOTALS&AVERAGES'!N6 | AJ6: =AI6-AH6 -> 0
A7: =JAN!A7 -> Reimbursement | AH7: =sum(B7:AF7) -> 0 | AI7: ='TOTALS&AVERAGES'!N7 | AJ7: =AI7-AH7 -> 0
A8: =JAN!A8 -> Government Assistance | AH8: =sum(B8:AF8) -> 0 | AI8: ='TOTALS&AVERAGES'!N8 | AJ8: =AI8-AH8 -> 0
A9: =JAN!A9 -> Side Hustles | AH9: =sum(B9:AF9) -> 0 | AI9: ='TOTALS&AVERAGES'!N9 | AJ9: =AI9-AH9 -> 0
A10: =JAN!A10 -> Interest/Rewards | AH10: =sum(B10:AF10) -> 0 | AI10: ='TOTALS&AVERAGES'!N10 | AJ10: =AI10-AH10 -> 0
A11: =JAN!A11 -> VA Benefits | AH11: =sum(B11:AF11) -> 0 | AI11: ='TOTALS&AVERAGES'!N11 | AJ11: =AI11-AH11 -> 0
A12: =JAN!A12 -> Asset Cash Out | AH12: =sum(B12:AF12) -> 0 | AI12: ='TOTALS&AVERAGES'!N12 | AJ12: =AI12-AH12 -> 0
A13: =JAN!A13 -> Fed Tax Refund | AH13: =sum(B13:AF13) -> 0 | AI13: ='TOTALS&AVERAGES'!N13 | AJ13: =AI13-AH13 -> 0
A14: =JAN!A14 -> State Tax Refund | AH14: =sum(B14:AF14) -> 0 | AI14: ='TOTALS&AVERAGES'!N14 | AJ14: =AI14-AH14 -> 0
A15: TOTAL INCOME BEFORE TAXES | B15: =SUM(C3:AH14) -> 0 | C15: =SUM(C3:C14) -> 0 | D15: =SUM(D3:D14) -> 0 | E15: =SUM(E3:E14) -> 0 | F15: =SUM(F3:F14) -> 0 | G15: =SUM(G3:G14) -> 0 | H15: =SUM(H3:H14) -> 0 | I15: =SUM(I3:I14) -> 0 | J15: =SUM(J3:J14) -> 0 | ... AJ15: =SUM(AJ3:AJ14) -> 0
A16: EXPENSES BY D.A. CATEGORIES | B16: MONTHLY REGULAR BILLS
A17: 1 - SPIRITUAL | B17: =SUM(B18:B26) -> 0 | C17: =SUM(C18:C26) -> 0 | D17: =SUM(D18:D26) -> 0 | E17: =SUM(E18:E26) -> 0 | F17: =SUM(F18:F26) -> 0 | G17: =SUM(G18:G26) -> 0 | H17: =SUM(H18:H26) -> 0 | I17: =SUM(I18:I26) -> 0 | ... AJ17: =SUM(AJ18:AJ26) -> 0
A18: =JAN!A18 -> Tithing/Church Donation | AH18: =sum(B18:AF18) -> 0 | AI18: ='TOTALS&AVERAGES'!N18 | AJ18: =AI18-AH18 -> 0
A19: =JAN!A19 -> Books | AH19: =sum(B19:AF19) -> 0 | AI19: ='TOTALS&AVERAGES'!N19 | AJ19: =AI19-AH19 -> 0
A20: =JAN!A20 -> Charity | AH20: =sum(B20:AF20) -> 0 | AI20: ='TOTALS&AVERAGES'!N20 | AJ20: =AI20-AH20 -> 0
A21: =JAN!A21 -> Workshops | AH21: =sum(B21:AF21) -> 0 | AI21: ='TOTALS&AVERAGES'!N21 | AJ21: =AI21-AH21 -> 0
A22: =JAN!A22 -> Generosity | AH22: =sum(B22:AF22) -> 0 | AI22: ='TOTALS&AVERAGES'!N22 | AJ22: =AI22-AH22 -> 0
A23: =JAN!A23 -> Retreats / Seminars | AH23: =sum(B23:AF23) -> 0 | AI23: ='TOTALS&AVERAGES'!N23 | AJ23: =AI23-AH23 -> 0
A24: =JAN!A24 -> 7TH TRADITION / FELLOWSHIP/ PRG | AH24: =sum(B24:AF24) -> 0 | AI24: ='TOTALS&AVERAGES'!N24 | AJ24: =AI24-AH24 -> 0
A25: =JAN!A25 -> Conferences | AH25: =sum(B25:AF25) -> 0 | AI25: ='TOTALS&AVERAGES'!N25 | AJ25: =AI25-AH25 -> 0
A26: =JAN!A26 -> Career Investment | AH26: =sum(B26:AF26) -> 0 | AI26: ='TOTALS&AVERAGES'!N26 | AJ26: =AI26-AH26 -> 0
A27: =JAN!A27 -> Needs | B27: =SUM(B28:B43) -> 0 | C27: =SUM(C28:C43) -> 0 | D27: =SUM(D28:D43) -> 0 | E27: =SUM(E28:E43) -> 0 | F27: =SUM(F28:F43) -> 0 | G27: =SUM(G28:G43) -> 0 | H27: =SUM(H28:H43) -> 0 | I27: =SUM(I28:I43) -> 0 | ... AJ27: =SUM(AJ28:AJ43) -> 0
A28: =JAN!A28 -> Groceries | AH28: =sum(B28:AF28) -> 0 | AI28: ='TOTALS&AVERAGES'!N28 | AJ28: =AI28-AH28 -> 0
A29: =JAN!A29 -> Rent/Mortage | B29: * | AH29: =sum(B29:AF29) -> 0 | AI29: ='TOTALS&AVERAGES'!N29 | AJ29: =AI29-AH29 -> 0
A30: =JAN!A30 -> Cell Phone | B30: * | AH30: =sum(B30:AF30) -> 0 | AI30: ='TOTALS&AVERAGES'!N30 | AJ30: =AI30-AH30 -> 0
A31: =JAN!A31 -> Laundry/Cleaners | B31: * | AH31: =sum(B31:AF31) -> 0 | AI31: ='TOTALS&AVERAGES'!N31 | AJ31: =AI31-AH31 -> 0
A32: =JAN!A32 -> Car Fuel | B32: * | AH32: =sum(B32:AF32) -> 0 | AI32: ='TOTALS&AVERAGES'!N32 | AJ32: =AI32-AH32 -> 0
A33: =JAN!A33 -> Car Insurance | B33: * | AH33: =sum(B33:AF33) -> 0 | AI33: ='TOTALS&AVERAGES'!N33 | AJ33: =AI33-AH33 -> 0
A34: =JAN!A34 -> Home Items | B34: * | AH34: =sum(B34:AF34) -> 0 | AI34: ='TOTALS&AVERAGES'!N34 | AJ34: =AI34-AH34 -> 0
A35: =JAN!A35 -> Internet | AH35: =sum(B35:AF35) -> 0 | AI35: ='TOTALS&AVERAGES'!N35 | AJ35: =AI35-AH35 -> 0
A36: =JAN!A36 -> Electricity | B36: * | AH36: =sum(B36:AF36) -> 0 | AI36: ='TOTALS&AVERAGES'!N36 | AJ36: =AI36-AH36 -> 0
A37: =JAN!A37 -> Card Fees | AH37: =sum(B37:AF37) -> 0 | AI37: ='TOTALS&AVERAGES'!N37 | AJ37: =AI37-AH37 -> 0
A38: =JAN!A38 -> Moving | AH38: =sum(B38:AF38) -> 0 | AI38: ='TOTALS&AVERAGES'!N38 | AJ38: =AI38-AH38 -> 0
A39: =JAN!A39 -> Toiletries | B39: * | AH39: =sum(B39:AF39) -> 0 | AI39: ='TOTALS&AVERAGES'!N39 | AJ39: =AI39-AH39 -> 0
A40: =JAN!A40 -> Storage | B40: * | AH40: =sum(B40:AF40) -> 0 | AI40: ='TOTALS&AVERAGES'!N40 | AJ40: =AI40-AH40 -> 0
...

Sheet MAY
A1: MAY | B1: Monthly Regular Bills | C1: 46143 | D1: =C1+1 -> 46144 | E1: =D1+1 -> 46145 | F1: =E1+1 -> 46146 | G1: =F1+1 -> 46147 | H1: =G1+1 -> 46148 | I1: =H1+1 -> 46149 | J1: =I1+1 -> 46150 | K1: =J1+1 -> 46151 | ... AG1: =AF1+1 -> 46173 | AH1: TOTALS | AI1: SPENDING PLAN | AJ1: DIFFERENCE
A2: INCOME
A3: =JAN!A3 -> Main Job | AH3: =sum(B3:AF3) -> 0 | AI3: ='TOTALS&AVERAGES'!N3 | AJ3: =AI3-AH3 -> 0
A4: =JAN!A4 -> B Job | AH4: =sum(B4:AF4) -> 0 | AI4: ='TOTALS&AVERAGES'!N4 | AJ4: =AI4-AH4 -> 0
A5: =JAN!A5 -> Bonuses | AH5: =sum(B5:AF5) -> 0 | AI5: ='TOTALS&AVERAGES'!N5 | AJ5: =AI5-AH5 -> 0
A6: =JAN!A6 -> Gifts/Discounts | AH6: =sum(B6:AF6) -> 0 | AI6: ='TOTALS&AVERAGES'!N6 | AJ6: =AI6-AH6 -> 0
A7: =JAN!A7 -> Reimbursement | AH7: =sum(B7:AF7) -> 0 | AI7: ='TOTALS&AVERAGES'!N7 | AJ7: =AI7-AH7 -> 0
A8: =JAN!A8 -> Government Assistance | AH8: =sum(B8:AF8) -> 0 | AI8: ='TOTALS&AVERAGES'!N8 | AJ8: =AI8-AH8 -> 0
A9: =JAN!A9 -> Side Hustles | AH9: =sum(B9:AF9) -> 0 | AI9: ='TOTALS&AVERAGES'!N9 | AJ9: =AI9-AH9 -> 0
A10: =JAN!A10 -> Interest/Rewards | AH10: =sum(B10:AF10) -> 0 | AI10: ='TOTALS&AVERAGES'!N10 | AJ10: =AI10-AH10 -> 0
A11: =JAN!A11 -> VA Benefits | AH11: =sum(B11:AF11) -> 0 | AI11: ='TOTALS&AVERAGES'!N11 | AJ11: =AI11-AH11 -> 0
A12: =JAN!A12 -> Asset Cash Out | AH12: =sum(B12:AF12) -> 0 | AI12: ='TOTALS&AVERAGES'!N12 | AJ12: =AI12-AH12 -> 0
A13: =JAN!A13 -> Fed Tax Refund | AH13: =sum(B13:AF13) -> 0 | AI13: ='TOTALS&AVERAGES'!N13 | AJ13: =AI13-AH13 -> 0
A14: =JAN!A14 -> State Tax Refund | AH14: =sum(B14:AF14) -> 0 | AI14: ='TOTALS&AVERAGES'!N14 | AJ14: =AI14-AH14 -> 0
A15: TOTAL INCOME BEFORE TAXES | B15: =SUM(C3:AH14) -> 0 | C15: =SUM(C3:C14) -> 0 | D15: =SUM(D3:D14) -> 0 | E15: =SUM(E3:E14) -> 0 | F15: =SUM(F3:F14) -> 0 | G15: =SUM(G3:G14) -> 0 | H15: =SUM(H3:H14) -> 0 | I15: =SUM(I3:I14) -> 0 | J15: =SUM(J3:J14) -> 0 | ... AJ15: =SUM(AJ3:AJ14) -> 0
A16: EXPENSES BY D.A. CATEGORIES | B16: MONTHLY REGULAR BILLS
A17: 1 - SPIRITUAL | B17: =SUM(B18:B26) -> 0 | C17: =SUM(C18:C26) -> 0 | D17: =SUM(D18:D26) -> 0 | E17: =SUM(E18:E26) -> 0 | F17: =SUM(F18:F26) -> 0 | G17: =SUM(G18:G26) -> 0 | H17: =SUM(H18:H26) -> 0 | I17: =SUM(I18:I26) -> 0 | ... AJ17: =SUM(AJ18:AJ26) -> 0
A18: =JAN!A18 -> Tithing/Church Donation | AH18: =sum(B18:AF18) -> 0 | AI18: ='TOTALS&AVERAGES'!N18 | AJ18: =AI18-AH18 -> 0
A19: =JAN!A19 -> Books | AH19: =sum(B19:AF19) -> 0 | AI19: ='TOTALS&AVERAGES'!N19 | AJ19: =AI19-AH19 -> 0
A20: =JAN!A20 -> Charity | AH20: =sum(B20:AF20) -> 0 | AI20: ='TOTALS&AVERAGES'!N20 | AJ20: =AI20-AH20 -> 0
A21: =JAN!A21 -> Workshops | AH21: =sum(B21:AF21) -> 0 | AI21: ='TOTALS&AVERAGES'!N21 | AJ21: =AI21-AH21 -> 0
A22: =JAN!A22 -> Generosity | AH22: =sum(B22:AF22) -> 0 | AI22: ='TOTALS&AVERAGES'!N22 | AJ22: =AI22-AH22 -> 0
A23: =JAN!A23 -> Retreats / Seminars | AH23: =sum(B23:AF23) -> 0 | AI23: ='TOTALS&AVERAGES'!N23 | AJ23: =AI23-AH23 -> 0
A24: =JAN!A24 -> 7TH TRADITION / FELLOWSHIP/ PRG | AH24: =sum(B24:AF24) -> 0 | AI24: ='TOTALS&AVERAGES'!N24 | AJ24: =AI24-AH24 -> 0
A25: =JAN!A25 -> Conferences | AH25: =sum(B25:AF25) -> 0 | AI25: ='TOTALS&AVERAGES'!N25 | AJ25: =AI25-AH25 -> 0
A26: =JAN!A26 -> Career Investment | AH26: =sum(B26:AF26) -> 0 | AI26: ='TOTALS&AVERAGES'!N26 | AJ26: =AI26-AH26 -> 0
A27: =JAN!A27 -> Needs | B27: =SUM(B28:B43) -> 0 | C27: =SUM(C28:C43) -> 0 | D27: =SUM(D28:D43) -> 0 | E27: =SUM(E28:E43) -> 0 | F27: =SUM(F28:F43) -> 0 | G27: =SUM(G28:G43) -> 0 | H27: =SUM(H28:H43) -> 0 | I27: =SUM(I28:I43) -> 0 | ... AJ27: =SUM(AJ28:AJ43) -> 0
A28: =JAN!A28 -> Groceries | AH28: =sum(B28:AF28) -> 0 | AI28: ='TOTALS&AVERAGES'!N28 | AJ28: =AI28-AH28 -> 0
A29: =JAN!A29 -> Rent/Mortage | B29: * | AH29: =sum(B29:AF29) -> 0 | AI29: ='TOTALS&AVERAGES'!N29 | AJ29: =AI29-AH29 -> 0
A30: =JAN!A30 -> Cell Phone | B30: * | AH30: =sum(B30:AF30) -> 0 | AI30: ='TOTALS&AVERAGES'!N30 | AJ30: =AI30-AH30 -> 0
A31: =JAN!A31 -> Laundry/Cleaners | B31: * | AH31: =sum(B31:AF31) -> 0 | AI31: ='TOTALS&AVERAGES'!N31 | AJ31: =AI31-AH31 -> 0
A32: =JAN!A32 -> Car Fuel | B32: * | AH32: =sum(B32:AF32) -> 0 | AI32: ='TOTALS&AVERAGES'!N32 | AJ32: =AI32-AH32 -> 0
A33: =JAN!A33 -> Car Insurance | B33: * | AH33: =sum(B33:AF33) -> 0 | AI33: ='TOTALS&AVERAGES'!N33 | AJ33: =AI33-AH33 -> 0
A34: =JAN!A34 -> Home Items | B34: * | AH34: =sum(B34:AF34) -> 0 | AI34: ='TOTALS&AVERAGES'!N34 | AJ34: =AI34-AH34 -> 0
A35: =JAN!A35 -> Internet | AH35: =sum(B35:AF35) -> 0 | AI35: ='TOTALS&AVERAGES'!N35 | AJ35: =AI35-AH35 -> 0
A36: =JAN!A36 -> Electricity | B36: * | AH36: =sum(B36:AF36) -> 0 | AI36: ='TOTALS&AVERAGES'!N36 | AJ36: =AI36-AH36 -> 0
A37: =JAN!A37 -> Card Fees | AH37: =sum(B37:AF37) -> 0 | AI37: ='TOTALS&AVERAGES'!N37 | AJ37: =AI37-AH37 -> 0
A38: =JAN!A38 -> Moving | AH38: =sum(B38:AF38) -> 0 | AI38: ='TOTALS&AVERAGES'!N38 | AJ38: =AI38-AH38 -> 0
A39: =JAN!A39 -> Toiletries | B39: * | AH39: =sum(B39:AF39) -> 0 | AI39: ='TOTALS&AVERAGES'!N39 | AJ39: =AI39-AH39 -> 0
A40: =JAN!A40 -> Storage | B40: * | AH40: =sum(B40:AF40) -> 0 | AI40: ='TOTALS&AVERAGES'!N40 | AJ40: =AI40-AH40 -> 0
...

Sheet JUN
A1: JUNE | B1: Monthly Regular Bills | C1: 46174 | D1: =C1+1 -> 46175 | E1: =D1+1 -> 46176 | F1: =E1+1 -> 46177 | G1: =F1+1 -> 46178 | H1: =G1+1 -> 46179 | I1: =H1+1 -> 46180 | J1: =I1+1 -> 46181 | K1: =J1+1 -> 46182 | ... AG1: =AF1+1 -> 46204 | AH1: TOTALS | AI1: SPENDING PLAN | AJ1: DIFFERENCE
A2: INCOME
A3: =JAN!A3 -> Main Job | AH3: =sum(B3:AF3) -> 0 | AI3: ='TOTALS&AVERAGES'!N3 | AJ3: =AI3-AH3 -> 0
A4: =JAN!A4 -> B Job | AH4: =sum(B4:AF4) -> 0 | AI4: ='TOTALS&AVERAGES'!N4 | AJ4: =AI4-AH4 -> 0
A5: =JAN!A5 -> Bonuses | AH5: =sum(B5:AF5) -> 0 | AI5: ='TOTALS&AVERAGES'!N5 | AJ5: =AI5-AH5 -> 0
A6: =JAN!A6 -> Gifts/Discounts | AH6: =sum(B6:AF6) -> 0 | AI6: ='TOTALS&AVERAGES'!N6 | AJ6: =AI6-AH6 -> 0
A7: =JAN!A7 -> Reimbursement | AH7: =sum(B7:AF7) -> 0 | AI7: ='TOTALS&AVERAGES'!N7 | AJ7: =AI7-AH7 -> 0
A8: =JAN!A8 -> Government Assistance | AH8: =sum(B8:AF8) -> 0 | AI8: ='TOTALS&AVERAGES'!N8 | AJ8: =AI8-AH8 -> 0
A9: =JAN!A9 -> Side Hustles | AH9: =sum(B9:AF9) -> 0 | AI9: ='TOTALS&AVERAGES'!N9 | AJ9: =AI9-AH9 -> 0
A10: =JAN!A10 -> Interest/Rewards | AH10: =sum(B10:AF10) -> 0 | AI10: ='TOTALS&AVERAGES'!N10 | AJ10: =AI10-AH10 -> 0
A11: =JAN!A11 -> VA Benefits | AH11: =sum(B11:AF11) -> 0 | AI11: ='TOTALS&AVERAGES'!N11 | AJ11: =AI11-AH11 -> 0
A12: =JAN!A12 -> Asset Cash Out | AH12: =sum(B12:AF12) -> 0 | AI12: ='TOTALS&AVERAGES'!N12 | AJ12: =AI12-AH12 -> 0
A13: =JAN!A13 -> Fed Tax Refund | AH13: =sum(B13:AF13) -> 0 | AI13: ='TOTALS&AVERAGES'!N13 | AJ13: =AI13-AH13 -> 0
A14: =JAN!A14 -> State Tax Refund | AH14: =sum(B14:AF14) -> 0 | AI14: ='TOTALS&AVERAGES'!N14 | AJ14: =AI14-AH14 -> 0
A15: TOTAL INCOME BEFORE TAXES | B15: =SUM(C3:AH14) -> 0 | C15: =SUM(C3:C14) -> 0 | D15: =SUM(D3:D14) -> 0 | E15: =SUM(E3:E14) -> 0 | F15: =SUM(F3:F14) -> 0 | G15: =SUM(G3:G14) -> 0 | H15: =SUM(H3:H14) -> 0 | I15: =SUM(I3:I14) -> 0 | J15: =SUM(J3:J14) -> 0 | ... AJ15: =SUM(AJ3:AJ14) -> 0
A16: EXPENSES BY D.A. CATEGORIES | B16: MONTHLY REGULAR BILLS
A17: 1 - SPIRITUAL | B17: =SUM(B18:B26) -> 0 | C17: =SUM(C18:C26) -> 0 | D17: =SUM(D18:D26) -> 0 | E17: =SUM(E18:E26) -> 0 | F17: =SUM(F18:F26) -> 0 | G17: =SUM(G18:G26) -> 0 | H17: =SUM(H18:H26) -> 0 | I17: =SUM(I18:I26) -> 0 | ... AJ17: =SUM(AJ18:AJ26) -> 0
A18: =JAN!A18 -> Tithing/Church Donation | AH18: =sum(B18:AF18) -> 0 | AI18: ='TOTALS&AVERAGES'!N18 | AJ18: =AI18-AH18 -> 0
A19: =JAN!A19 -> Books | AH19: =sum(B19:AF19) -> 0 | AI19: ='TOTALS&AVERAGES'!N19 | AJ19: =AI19-AH19 -> 0
A20: =JAN!A20 -> Charity | AH20: =sum(B20:AF20) -> 0 | AI20: ='TOTALS&AVERAGES'!N20 | AJ20: =AI20-AH20 -> 0
A21: =JAN!A21 -> Workshops | AH21: =sum(B21:AF21) -> 0 | AI21: ='TOTALS&AVERAGES'!N21 | AJ21: =AI21-AH21 -> 0
A22: =JAN!A22 -> Generosity | AH22: =sum(B22:AF22) -> 0 | AI22: ='TOTALS&AVERAGES'!N22 | AJ22: =AI22-AH22 -> 0
A23: =JAN!A23 -> Retreats / Seminars | AH23: =sum(B23:AF23) -> 0 | AI23: ='TOTALS&AVERAGES'!N23 | AJ23: =AI23-AH23 -> 0
A24: =JAN!A24 -> 7TH TRADITION / FELLOWSHIP/ PRG | AH24: =sum(B24:AF24) -> 0 | AI24: ='TOTALS&AVERAGES'!N24 | AJ24: =AI24-AH24 -> 0
A25: =JAN!A25 -> Conferences | AH25: =sum(B25:AF25) -> 0 | AI25: ='TOTALS&AVERAGES'!N25 | AJ25: =AI25-AH25 -> 0
A26: =JAN!A26 -> Career Investment | AH26: =sum(B26:AF26) -> 0 | AI26: ='TOTALS&AVERAGES'!N26 | AJ26: =AI26-AH26 -> 0
A27: =JAN!A27 -> Needs | B27: =SUM(B28:B43) -> 0 | C27: =SUM(C28:C43) -> 0 | D27: =SUM(D28:D43) -> 0 | E27: =SUM(E28:E43) -> 0 | F27: =SUM(F28:F43) -> 0 | G27: =SUM(G28:G43) -> 0 | H27: =SUM(H28:H43) -> 0 | I27: =SUM(I28:I43) -> 0 | ... AJ27: =SUM(AJ28:AJ43) -> 0
A28: =JAN!A28 -> Groceries | AH28: =sum(B28:AF28) -> 0 | AI28: ='TOTALS&AVERAGES'!N28 | AJ28: =AI28-AH28 -> 0
A29: =JAN!A29 -> Rent/Mortage | B29: * | AH29: =sum(B29:AF29) -> 0 | AI29: ='TOTALS&AVERAGES'!N29 | AJ29: =AI29-AH29 -> 0
A30: =JAN!A30 -> Cell Phone | B30: * | AH30: =sum(B30:AF30) -> 0 | AI30: ='TOTALS&AVERAGES'!N30 | AJ30: =AI30-AH30 -> 0
A31: =JAN!A31 -> Laundry/Cleaners | B31: * | AH31: =sum(B31:AF31) -> 0 | AI31: ='TOTALS&AVERAGES'!N31 | AJ31: =AI31-AH31 -> 0
A32: =JAN!A32 -> Car Fuel | B32: * | AH32: =sum(B32:AF32) -> 0 | AI32: ='TOTALS&AVERAGES'!N32 | AJ32: =AI32-AH32 -> 0
A33: =JAN!A33 -> Car Insurance | B33: * | AH33: =sum(B33:AF33) -> 0 | AI33: ='TOTALS&AVERAGES'!N33 | AJ33: =AI33-AH33 -> 0
A34: =JAN!A34 -> Home Items | B34: * | AH34: =sum(B34:AF34) -> 0 | AI34: ='TOTALS&AVERAGES'!N34 | AJ34: =AI34-AH34 -> 0
A35: =JAN!A35 -> Internet | AH35: =sum(B35:AF35) -> 0 | AI35: ='TOTALS&AVERAGES'!N35 | AJ35: =AI35-AH35 -> 0
A36: =JAN!A36 -> Electricity | B36: * | AH36: =sum(B36:AF36) -> 0 | AI36: ='TOTALS&AVERAGES'!N36 | AJ36: =AI36-AH36 -> 0
A37: =JAN!A37 -> Card Fees | AH37: =sum(B37:AF37) -> 0 | AI37: ='TOTALS&AVERAGES'!N37 | AJ37: =AI37-AH37 -> 0
A38: =JAN!A38 -> Moving | AH38: =sum(B38:AF38) -> 0 | AI38: ='TOTALS&AVERAGES'!N38 | AJ38: =AI38-AH38 -> 0
A39: =JAN!A39 -> Toiletries | B39: * | AH39: =sum(B39:AF39) -> 0 | AI39: ='TOTALS&AVERAGES'!N39 | AJ39: =AI39-AH39 -> 0
A40: =JAN!A40 -> Storage | B40: * | AH40: =sum(B40:AF40) -> 0 | AI40: ='TOTALS&AVERAGES'!N40 | AJ40: =AI40-AH40 -> 0
...

Sheet JUL
A1: JUL | B1: Monthly Regular Bills | C1: 46204 | D1: =C1+1 -> 46205 | E1: =D1+1 -> 46206 | F1: =E1+1 -> 46207 | G1: =F1+1 -> 46208 | H1: =G1+1 -> 46209 | I1: =H1+1 -> 46210 | J1: =I1+1 -> 46211 | K1: =J1+1 -> 46212 | ... AG1: =AF1+1 -> 46234 | AH1: TOTALS | AI1: SPENDING PLAN | AJ1: DIFFERENCE
A2: INCOME
A3: =JAN!A3 -> Main Job | AH3: =sum(B3:AF3) -> 0 | AI3: ='TOTALS&AVERAGES'!N3 | AJ3: =AI3-AH3 -> 0
A4: =JAN!A4 -> B Job | AH4: =sum(B4:AF4) -> 0 | AI4: ='TOTALS&AVERAGES'!N4 | AJ4: =AI4-AH4 -> 0
A5: =JAN!A5 -> Bonuses | AH5: =sum(B5:AF5) -> 0 | AI5: ='TOTALS&AVERAGES'!N5 | AJ5: =AI5-AH5 -> 0
A6: =JAN!A6 -> Gifts/Discounts | AH6: =sum(B6:AF6) -> 0 | AI6: ='TOTALS&AVERAGES'!N6 | AJ6: =AI6-AH6 -> 0
A7: =JAN!A7 -> Reimbursement | AH7: =sum(B7:AF7) -> 0 | AI7: ='TOTALS&AVERAGES'!N7 | AJ7: =AI7-AH7 -> 0
A8: =JAN!A8 -> Government Assistance | AH8: =sum(B8:AF8) -> 0 | AI8: ='TOTALS&AVERAGES'!N8 | AJ8: =AI8-AH8 -> 0
A9: =JAN!A9 -> Side Hustles | AH9: =sum(B9:AF9) -> 0 | AI9: ='TOTALS&AVERAGES'!N9 | AJ9: =AI9-AH9 -> 0
A10: =JAN!A10 -> Interest/Rewards | AH10: =sum(B10:AF10) -> 0 | AI10: ='TOTALS&AVERAGES'!N10 | AJ10: =AI10-AH10 -> 0
A11: =JAN!A11 -> VA Benefits | AH11: =sum(B11:AF11) -> 0 | AI11: ='TOTALS&AVERAGES'!N11 | AJ11: =AI11-AH11 -> 0
A12: =JAN!A12 -> Asset Cash Out | AH12: =sum(B12:AF12) -> 0 | AI12: ='TOTALS&AVERAGES'!N12 | AJ12: =AI12-AH12 -> 0
A13: =JAN!A13 -> Fed Tax Refund | AH13: =sum(B13:AF13) -> 0 | AI13: ='TOTALS&AVERAGES'!N13 | AJ13: =AI13-AH13 -> 0
A14: =JAN!A14 -> State Tax Refund | AH14: =sum(B14:AF14) -> 0 | AI14: ='TOTALS&AVERAGES'!N14 | AJ14: =AI14-AH14 -> 0
A15: TOTAL INCOME BEFORE TAXES | B15: =SUM(C3:AH14) -> 0 | C15: =SUM(C3:C14) -> 0 | D15: =SUM(D3:D14) -> 0 | E15: =SUM(E3:E14) -> 0 | F15: =SUM(F3:F14) -> 0 | G15: =SUM(G3:G14) -> 0 | H15: =SUM(H3:H14) -> 0 | I15: =SUM(I3:I14) -> 0 | J15: =SUM(J3:J14) -> 0 | ... AJ15: =SUM(AJ3:AJ14) -> 0
A16: EXPENSES BY D.A. CATEGORIES | B16: MONTHLY REGULAR BILLS
A17: 1 - SPIRITUAL | B17: =SUM(B18:B26) -> 0 | C17: =SUM(C18:C26) -> 0 | D17: =SUM(D18:D26) -> 0 | E17: =SUM(E18:E26) -> 0 | F17: =SUM(F18:F26) -> 0 | G17: =SUM(G18:G26) -> 0 | H17: =SUM(H18:H26) -> 0 | I17: =SUM(I18:I26) -> 0 | ... AJ17: =SUM(AJ18:AJ26) -> 0
A18: =JAN!A18 -> Tithing/Church Donation | AH18: =sum(B18:AF18) -> 0 | AI18: ='TOTALS&AVERAGES'!N18 | AJ18: =AI18-AH18 -> 0
A19: =JAN!A19 -> Books | AH19: =sum(B19:AF19) -> 0 | AI19: ='TOTALS&AVERAGES'!N19 | AJ19: =AI19-AH19 -> 0
A20: =JAN!A20 -> Charity | AH20: =sum(B20:AF20) -> 0 | AI20: ='TOTALS&AVERAGES'!N20 | AJ20: =AI20-AH20 -> 0
A21: =JAN!A21 -> Workshops | AH21: =sum(B21:AF21) -> 0 | AI21: ='TOTALS&AVERAGES'!N21 | AJ21: =AI21-AH21 -> 0
A22: =JAN!A22 -> Generosity | AH22: =sum(B22:AF22) -> 0 | AI22: ='TOTALS&AVERAGES'!N22 | AJ22: =AI22-AH22 -> 0
A23: =JAN!A23 -> Retreats / Seminars | AH23: =sum(B23:AF23) -> 0 | AI23: ='TOTALS&AVERAGES'!N23 | AJ23: =AI23-AH23 -> 0
A24: =JAN!A24 -> 7TH TRADITION / FELLOWSHIP/ PRG | AH24: =sum(B24:AF24) -> 0 | AI24: ='TOTALS&AVERAGES'!N24 | AJ24: =AI24-AH24 -> 0
A25: =JAN!A25 -> Conferences | AH25: =sum(B25:AF25) -> 0 | AI25: ='TOTALS&AVERAGES'!N25 | AJ25: =AI25-AH25 -> 0
A26: =JAN!A26 -> Career Investment | AH26: =sum(B26:AF26) -> 0 | AI26: ='TOTALS&AVERAGES'!N26 | AJ26: =AI26-AH26 -> 0
A27: =JAN!A27 -> Needs | B27: =SUM(B28:B43) -> 0 | C27: =SUM(C28:C43) -> 0 | D27: =SUM(D28:D43) -> 0 | E27: =SUM(E28:E43) -> 0 | F27: =SUM(F28:F43) -> 0 | G27: =SUM(G28:G43) -> 0 | H27: =SUM(H28:H43) -> 0 | I27: =SUM(I28:I43) -> 0 | ... AJ27: =SUM(AJ28:AJ43) -> 0
A28: =JAN!A28 -> Groceries | AH28: =sum(B28:AF28) -> 0 | AI28: ='TOTALS&AVERAGES'!N28 | AJ28: =AI28-AH28 -> 0
A29: =JAN!A29 -> Rent/Mortage | B29: * | AH29: =sum(B29:AF29) -> 0 | AI29: ='TOTALS&AVERAGES'!N29 | AJ29: =AI29-AH29 -> 0
A30: =JAN!A30 -> Cell Phone | B30: * | AH30: =sum(B30:AF30) -> 0 | AI30: ='TOTALS&AVERAGES'!N30 | AJ30: =AI30-AH30 -> 0
A31: =JAN!A31 -> Laundry/Cleaners | B31: * | AH31: =sum(B31:AF31) -> 0 | AI31: ='TOTALS&AVERAGES'!N31 | AJ31: =AI31-AH31 -> 0
A32: =JAN!A32 -> Car Fuel | B32: * | AH32: =sum(B32:AF32) -> 0 | AI32: ='TOTALS&AVERAGES'!N32 | AJ32: =AI32-AH32 -> 0
A33: =JAN!A33 -> Car Insurance | B33: * | AH33: =sum(B33:AF33) -> 0 | AI33: ='TOTALS&AVERAGES'!N33 | AJ33: =AI33-AH33 -> 0
A34: =JAN!A34 -> Home Items | B34: * | AH34: =sum(B34:AF34) -> 0 | AI34: ='TOTALS&AVERAGES'!N34 | AJ34: =AI34-AH34 -> 0
A35: =JAN!A35 -> Internet | AH35: =sum(B35:AF35) -> 0 | AI35: ='TOTALS&AVERAGES'!N35 | AJ35: =AI35-AH35 -> 0
A36: =JAN!A36 -> Electricity | B36: * | AH36: =sum(B36:AF36) -> 0 | AI36: ='TOTALS&AVERAGES'!N36 | AJ36: =AI36-AH36 -> 0
A37: =JAN!A37 -> Card Fees | AH37: =sum(B37:AF37) -> 0 | AI37: ='TOTALS&AVERAGES'!N37 | AJ37: =AI37-AH37 -> 0
A38: =JAN!A38 -> Moving | AH38: =sum(B38:AF38) -> 0 | AI38: ='TOTALS&AVERAGES'!N38 | AJ38: =AI38-AH38 -> 0
A39: =JAN!A39 -> Toiletries | B39: * | AH39: =sum(B39:AF39) -> 0 | AI39: ='TOTALS&AVERAGES'!N39 | AJ39: =AI39-AH39 -> 0
A40: =JAN!A40 -> Storage | B40: * | AH40: =sum(B40:AF40) -> 0 | AI40: ='TOTALS&AVERAGES'!N40 | AJ40: =AI40-AH40 -> 0
...

Sheet AUG
A1: AUGUST | B1: Monthly Regular Bills | C1: 46235 | D1: =C1+1 -> 46236 | E1: =D1+1 -> 46237 | F1: =E1+1 -> 46238 | G1: =F1+1 -> 46239 | H1: =G1+1 -> 46240 | I1: =H1+1 -> 46241 | J1: =I1+1 -> 46242 | K1: =J1+1 -> 46243 | ... AG1: =AF1+1 -> 46265 | AH1: TOTALS | AI1: SPENDING PLAN | AJ1: DIFFERENCE
A2: INCOME
A3: =JAN!A3 -> Main Job | AH3: =sum(B3:AF3) -> 0 | AI3: ='TOTALS&AVERAGES'!N3 | AJ3: =AI3-AH3 -> 0
A4: =JAN!A4 -> B Job | AH4: =sum(B4:AF4) -> 0 | AI4: ='TOTALS&AVERAGES'!N4 | AJ4: =AI4-AH4 -> 0
A5: =JAN!A5 -> Bonuses | AH5: =sum(B5:AF5) -> 0 | AI5: ='TOTALS&AVERAGES'!N5 | AJ5: =AI5-AH5 -> 0
A6: =JAN!A6 -> Gifts/Discounts | AH6: =sum(B6:AF6) -> 0 | AI6: ='TOTALS&AVERAGES'!N6 | AJ6: =AI6-AH6 -> 0
A7: =JAN!A7 -> Reimbursement | AH7: =sum(B7:AF7) -> 0 | AI7: ='TOTALS&AVERAGES'!N7 | AJ7: =AI7-AH7 -> 0
A8: =JAN!A8 -> Government Assistance | AH8: =sum(B8:AF8) -> 0 | AI8: ='TOTALS&AVERAGES'!N8 | AJ8: =AI8-AH8 -> 0
A9: =JAN!A9 -> Side Hustles | AH9: =sum(B9:AF9) -> 0 | AI9: ='TOTALS&AVERAGES'!N9 | AJ9: =AI9-AH9 -> 0
A10: =JAN!A10 -> Interest/Rewards | AH10: =sum(B10:AF10) -> 0 | AI10: ='TOTALS&AVERAGES'!N10 | AJ10: =AI10-AH10 -> 0
A11: =JAN!A11 -> VA Benefits | AH11: =sum(B11:AF11) -> 0 | AI11: ='TOTALS&AVERAGES'!N11 | AJ11: =AI11-AH11 -> 0
A12: =JAN!A12 -> Asset Cash Out | AH12: =sum(B12:AF12) -> 0 | AI12: ='TOTALS&AVERAGES'!N12 | AJ12: =AI12-AH12 -> 0
A13: =JAN!A13 -> Fed Tax Refund | AH13: =sum(B13:AF13) -> 0 | AI13: ='TOTALS&AVERAGES'!N13 | AJ13: =AI13-AH13 -> 0
A14: =JAN!A14 -> State Tax Refund | AH14: =sum(B14:AF14) -> 0 | AI14: ='TOTALS&AVERAGES'!N14 | AJ14: =AI14-AH14 -> 0
A15: TOTAL INCOME BEFORE TAXES | B15: =SUM(C3:AH14) -> 0 | C15: =SUM(C3:C14) -> 0 | D15: =SUM(D3:D14) -> 0 | E15: =SUM(E3:E14) -> 0 | F15: =SUM(F3:F14) -> 0 | G15: =SUM(G3:G14) -> 0 | H15: =SUM(H3:H14) -> 0 | I15: =SUM(I3:I14) -> 0 | J15: =SUM(J3:J14) -> 0 | ... AJ15: =SUM(AJ3:AJ14) -> 0
A16: EXPENSES BY D.A. CATEGORIES | B16: MONTHLY REGULAR BILLS
A17: 1 - SPIRITUAL | B17: =SUM(B18:B26) -> 0 | C17: =SUM(C18:C26) -> 0 | D17: =SUM(D18:D26) -> 0 | E17: =SUM(E18:E26) -> 0 | F17: =SUM(F18:F26) -> 0 | G17: =SUM(G18:G26) -> 0 | H17: =SUM(H18:H26) -> 0 | I17: =SUM(I18:I26) -> 0 | ... AJ17: =SUM(AJ18:AJ26) -> 0
A18: =JAN!A18 -> Tithing/Church Donation | AH18: =sum(B18:AF18) -> 0 | AI18: ='TOTALS&AVERAGES'!N18 | AJ18: =AI18-AH18 -> 0
A19: =JAN!A19 -> Books | AH19: =sum(B19:AF19) -> 0 | AI19: ='TOTALS&AVERAGES'!N19 | AJ19: =AI19-AH19 -> 0
A20: =JAN!A20 -> Charity | AH20: =sum(B20:AF20) -> 0 | AI20: ='TOTALS&AVERAGES'!N20 | AJ20: =AI20-AH20 -> 0
A21: =JAN!A21 -> Workshops | AH21: =sum(B21:AF21) -> 0 | AI21: ='TOTALS&AVERAGES'!N21 | AJ21: =AI21-AH21 -> 0
A22: =JAN!A22 -> Generosity | AH22: =sum(B22:AF22) -> 0 | AI22: ='TOTALS&AVERAGES'!N22 | AJ22: =AI22-AH22 -> 0
A23: =JAN!A23 -> Retreats / Seminars | AH23: =sum(B23:AF23) -> 0 | AI23: ='TOTALS&AVERAGES'!N23 | AJ23: =AI23-AH23 -> 0
A24: =JAN!A24 -> 7TH TRADITION / FELLOWSHIP/ PRG | AH24: =sum(B24:AF24) -> 0 | AI24: ='TOTALS&AVERAGES'!N24 | AJ24: =AI24-AH24 -> 0
A25: =JAN!A25 -> Conferences | AH25: =sum(B25:AF25) -> 0 | AI25: ='TOTALS&AVERAGES'!N25 | AJ25: =AI25-AH25 -> 0
A26: =JAN!A26 -> Career Investment | AH26: =sum(B26:AF26) -> 0 | AI26: ='TOTALS&AVERAGES'!N26 | AJ26: =AI26-AH26 -> 0
A27: =JAN!A27 -> Needs | B27: =SUM(B28:B43) -> 0 | C27: =SUM(C28:C43) -> 0 | D27: =SUM(D28:D43) -> 0 | E27: =SUM(E28:E43) -> 0 | F27: =SUM(F28:F43) -> 0 | G27: =SUM(G28:G43) -> 0 | H27: =SUM(H28:H43) -> 0 | I27: =SUM(I28:I43) -> 0 | ... AJ27: =SUM(AJ28:AJ43) -> 0
A28: =JAN!A28 -> Groceries | AH28: =sum(B28:AF28) -> 0 | AI28: ='TOTALS&AVERAGES'!N28 | AJ28: =AI28-AH28 -> 0
A29: =JAN!A29 -> Rent/Mortage | B29: * | AH29: =sum(B29:AF29) -> 0 | AI29: ='TOTALS&AVERAGES'!N29 | AJ29: =AI29-AH29 -> 0
A30: =JAN!A30 -> Cell Phone | B30: * | AH30: =sum(B30:AF30) -> 0 | AI30: ='TOTALS&AVERAGES'!N30 | AJ30: =AI30-AH30 -> 0
A31: =JAN!A31 -> Laundry/Cleaners | B31: * | AH31: =sum(B31:AF31) -> 0 | AI31: ='TOTALS&AVERAGES'!N31 | AJ31: =AI31-AH31 -> 0
A32: =JAN!A32 -> Car Fuel | B32: * | AH32: =sum(B32:AF32) -> 0 | AI32: ='TOTALS&AVERAGES'!N32 | AJ32: =AI32-AH32 -> 0
A33: =JAN!A33 -> Car Insurance | B33: * | AH33: =sum(B33:AF33) -> 0 | AI33: ='TOTALS&AVERAGES'!N33 | AJ33: =AI33-AH33 -> 0
A34: =JAN!A34 -> Home Items | B34: * | AH34: =sum(B34:AF34) -> 0 | AI34: ='TOTALS&AVERAGES'!N34 | AJ34: =AI34-AH34 -> 0
A35: =JAN!A35 -> Internet | AH35: =sum(B35:AF35) -> 0 | AI35: ='TOTALS&AVERAGES'!N35 | AJ35: =AI35-AH35 -> 0
A36: =JAN!A36 -> Electricity | B36: * | AH36: =sum(B36:AF36) -> 0 | AI36: ='TOTALS&AVERAGES'!N36 | AJ36: =AI36-AH36 -> 0
A37: =JAN!A37 -> Card Fees | AH37: =sum(B37:AF37) -> 0 | AI37: ='TOTALS&AVERAGES'!N37 | AJ37: =AI37-AH37 -> 0
A38: =JAN!A38 -> Moving | AH38: =sum(B38:AF38) -> 0 | AI38: ='TOTALS&AVERAGES'!N38 | AJ38: =AI38-AH38 -> 0
A39: =JAN!A39 -> Toiletries | B39: * | AH39: =sum(B39:AF39) -> 0 | AI39: ='TOTALS&AVERAGES'!N39 | AJ39: =AI39-AH39 -> 0
A40: =JAN!A40 -> Storage | B40: * | AH40: =sum(B40:AF40) -> 0 | AI40: ='TOTALS&AVERAGES'!N40 | AJ40: =AI40-AH40 -> 0
...

Sheet SEP
A1: SEPTEMBER | B1: Monthly Regular Bills | C1: 46266 | D1: =C1+1 -> 46267 | E1: =D1+1 -> 46268 | F1: =E1+1 -> 46269 | G1: =F1+1 -> 46270 | H1: =G1+1 -> 46271 | I1: =H1+1 -> 46272 | J1: =I1+1 -> 46273 | K1: =J1+1 -> 46274 | ... AG1: =AF1+1 -> 46296 | AH1: TOTALS | AI1: SPENDING PLAN | AJ1: DIFFERENCE
A2: INCOME
A3: =JAN!A3 -> Main Job | AH3: =sum(B3:AF3) -> 0 | AI3: ='TOTALS&AVERAGES'!N3 | AJ3: =AI3-AH3 -> 0
A4: =JAN!A4 -> B Job | AH4: =sum(B4:AF4) -> 0 | AI4: ='TOTALS&AVERAGES'!N4 | AJ4: =AI4-AH4 -> 0
A5: =JAN!A5 -> Bonuses | AH5: =sum(B5:AF5) -> 0 | AI5: ='TOTALS&AVERAGES'!N5 | AJ5: =AI5-AH5 -> 0
A6: =JAN!A6 -> Gifts/Discounts | AH6: =sum(B6:AF6) -> 0 | AI6: ='TOTALS&AVERAGES'!N6 | AJ6: =AI6-AH6 -> 0
A7: =JAN!A7 -> Reimbursement | AH7: =sum(B7:AF7) -> 0 | AI7: ='TOTALS&AVERAGES'!N7 | AJ7: =AI7-AH7 -> 0
A8: =JAN!A8 -> Government Assistance | AH8: =sum(B8:AF8) -> 0 | AI8: ='TOTALS&AVERAGES'!N8 | AJ8: =AI8-AH8 -> 0
A9: =JAN!A9 -> Side Hustles | AH9: =sum(B9:AF9) -> 0 | AI9: ='TOTALS&AVERAGES'!N9 | AJ9: =AI9-AH9 -> 0
A10: =JAN!A10 -> Interest/Rewards | AH10: =sum(B10:AF10) -> 0 | AI10: ='TOTALS&AVERAGES'!N10 | AJ10: =AI10-AH10 -> 0
A11: =JAN!A11 -> VA Benefits | AH11: =sum(B11:AF11) -> 0 | AI11: ='TOTALS&AVERAGES'!N11 | AJ11: =AI11-AH11 -> 0
A12: =JAN!A12 -> Asset Cash Out | AH12: =sum(B12:AF12) -> 0 | AI12: ='TOTALS&AVERAGES'!N12 | AJ12: =AI12-AH12 -> 0
A13: =JAN!A13 -> Fed Tax Refund | AH13: =sum(B13:AF13) -> 0 | AI13: ='TOTALS&AVERAGES'!N13 | AJ13: =AI13-AH13 -> 0
A14: =JAN!A14 -> State Tax Refund | AH14: =sum(B14:AF14) -> 0 | AI14: ='TOTALS&AVERAGES'!N14 | AJ14: =AI14-AH14 -> 0
A15: TOTAL INCOME BEFORE TAXES | B15: =SUM(C3:AH14) -> 0 | C15: =SUM(C3:C14) -> 0 | D15: =SUM(D3:D14) -> 0 | E15: =SUM(E3:E14) -> 0 | F15: =SUM(F3:F14) -> 0 | G15: =SUM(G3:G14) -> 0 | H15: =SUM(H3:H14) -> 0 | I15: =SUM(I3:I14) -> 0 | J15: =SUM(J3:J14) -> 0 | ... AJ15: =SUM(AJ3:AJ14) -> 0
A16: EXPENSES BY D.A. CATEGORIES | B16: MONTHLY REGULAR BILLS
A17: 1 - SPIRITUAL | B17: =SUM(B18:B26) -> 0 | C17: =SUM(C18:C26) -> 0 | D17: =SUM(D18:D26) -> 0 | E17: =SUM(E18:E26) -> 0 | F17: =SUM(F18:F26) -> 0 | G17: =SUM(G18:G26) -> 0 | H17: =SUM(H18:H26) -> 0 | I17: =SUM(I18:I26) -> 0 | ... AJ17: =SUM(AJ18:AJ26) -> 0
A18: =JAN!A18 -> Tithing/Church Donation | AH18: =sum(B18:AF18) -> 0 | AI18: ='TOTALS&AVERAGES'!N18 | AJ18: =AI18-AH18 -> 0
A19: =JAN!A19 -> Books | AH19: =sum(B19:AF19) -> 0 | AI19: ='TOTALS&AVERAGES'!N19 | AJ19: =AI19-AH19 -> 0
A20: =JAN!A20 -> Charity | AH20: =sum(B20:AF20) -> 0 | AI20: ='TOTALS&AVERAGES'!N20 | AJ20: =AI20-AH20 -> 0
A21: =JAN!A21 -> Workshops | AH21: =sum(B21:AF21) -> 0 | AI21: ='TOTALS&AVERAGES'!N21 | AJ21: =AI21-AH21 -> 0
A22: =JAN!A22 -> Generosity | AH22: =sum(B22:AF22) -> 0 | AI22: ='TOTALS&AVERAGES'!N22 | AJ22: =AI22-AH22 -> 0
A23: =JAN!A23 -> Retreats / Seminars | AH23: =sum(B23:AF23) -> 0 | AI23: ='TOTALS&AVERAGES'!N23 | AJ23: =AI23-AH23 -> 0
A24: =JAN!A24 -> 7TH TRADITION / FELLOWSHIP/ PRG | AH24: =sum(B24:AF24) -> 0 | AI24: ='TOTALS&AVERAGES'!N24 | AJ24: =AI24-AH24 -> 0
A25: =JAN!A25 -> Conferences | AH25: =sum(B25:AF25) -> 0 | AI25: ='TOTALS&AVERAGES'!N25 | AJ25: =AI25-AH25 -> 0
A26: =JAN!A26 -> Career Investment | AH26: =sum(B26:AF26) -> 0 | AI26: ='TOTALS&AVERAGES'!N26 | AJ26: =AI26-AH26 -> 0
A27: =JAN!A27 -> Needs | B27: =SUM(B28:B43) -> 0 | C27: =SUM(C28:C43) -> 0 | D27: =SUM(D28:D43) -> 0 | E27: =SUM(E28:E43) -> 0 | F27: =SUM(F28:F43) -> 0 | G27: =SUM(G28:G43) -> 0 | H27: =SUM(H28:H43) -> 0 | I27: =SUM(I28:I43) -> 0 | ... AJ27: =SUM(AJ28:AJ43) -> 0
A28: =JAN!A28 -> Groceries | AH28: =sum(B28:AF28) -> 0 | AI28: ='TOTALS&AVERAGES'!N28 | AJ28: =AI28-AH28 -> 0
A29: =JAN!A29 -> Rent/Mortage | B29: * | AH29: =sum(B29:AF29) -> 0 | AI29: ='TOTALS&AVERAGES'!N29 | AJ29: =AI29-AH29 -> 0
A30: =JAN!A30 -> Cell Phone | B30: * | AH30: =sum(B30:AF30) -> 0 | AI30: ='TOTALS&AVERAGES'!N30 | AJ30: =AI30-AH30 -> 0
A31: =JAN!A31 -> Laundry/Cleaners | B31: * | AH31: =sum(B31:AF31) -> 0 | AI31: ='TOTALS&AVERAGES'!N31 | AJ31: =AI31-AH31 -> 0
A32: =JAN!A32 -> Car Fuel | B32: * | AH32: =sum(B32:AF32) -> 0 | AI32: ='TOTALS&AVERAGES'!N32 | AJ32: =AI32-AH32 -> 0
A33: =JAN!A33 -> Car Insurance | B33: * | AH33: =sum(B33:AF33) -> 0 | AI33: ='TOTALS&AVERAGES'!N33 | AJ33: =AI33-AH33 -> 0
A34: =JAN!A34 -> Home Items | B34: * | AH34: =sum(B34:AF34) -> 0 | AI34: ='TOTALS&AVERAGES'!N34 | AJ34: =AI34-AH34 -> 0
A35: =JAN!A35 -> Internet | AH35: =sum(B35:AF35) -> 0 | AI35: ='TOTALS&AVERAGES'!N35 | AJ35: =AI35-AH35 -> 0
A36: =JAN!A36 -> Electricity | B36: * | AH36: =sum(B36:AF36) -> 0 | AI36: ='TOTALS&AVERAGES'!N36 | AJ36: =AI36-AH36 -> 0
A37: =JAN!A37 -> Card Fees | AH37: =sum(B37:AF37) -> 0 | AI37: ='TOTALS&AVERAGES'!N37 | AJ37: =AI37-AH37 -> 0
A38: =JAN!A38 -> Moving | AH38: =sum(B38:AF38) -> 0 | AI38: ='TOTALS&AVERAGES'!N38 | AJ38: =AI38-AH38 -> 0
A39: =JAN!A39 -> Toiletries | B39: * | AH39: =sum(B39:AF39) -> 0 | AI39: ='TOTALS&AVERAGES'!N39 | AJ39: =AI39-AH39 -> 0
A40: =JAN!A40 -> Storage | B40: * | AH40: =sum(B40:AF40) -> 0 | AI40: ='TOTALS&AVERAGES'!N40 | AJ40: =AI40-AH40 -> 0
...

Sheet OCT
A1: OCTOBER | B1: Monthly Regular Bills | C1: 46296 | D1: =C1+1 -> 46297 | E1: =D1+1 -> 46298 | F1: =E1+1 -> 46299 | G1: =F1+1 -> 46300 | H1: =G1+1 -> 46301 | I1: =H1+1 -> 46302 | J1: =I1+1 -> 46303 | K1: =J1+1 -> 46304 | ... AG1: =AF1+1 -> 46326 | AH1: TOTALS | AI1: SPENDING PLAN | AJ1: DIFFERENCE
A2: INCOME
A3: =JAN!A3 -> Main Job | AH3: =sum(B3:AF3) -> 0 | AI3: ='TOTALS&AVERAGES'!N3 | AJ3: =AI3-AH3 -> 0
A4: =JAN!A4 -> B Job | AH4: =sum(B4:AF4) -> 0 | AI4: ='TOTALS&AVERAGES'!N4 | AJ4: =AI4-AH4 -> 0
A5: =JAN!A5 -> Bonuses | AH5: =sum(B5:AF5) -> 0 | AI5: ='TOTALS&AVERAGES'!N5 | AJ5: =AI5-AH5 -> 0
A6: =JAN!A6 -> Gifts/Discounts | AH6: =sum(B6:AF6) -> 0 | AI6: ='TOTALS&AVERAGES'!N6 | AJ6: =AI6-AH6 -> 0
A7: =JAN!A7 -> Reimbursement | AH7: =sum(B7:AF7) -> 0 | AI7: ='TOTALS&AVERAGES'!N7 | AJ7: =AI7-AH7 -> 0
A8: =JAN!A8 -> Government Assistance | AH8: =sum(B8:AF8) -> 0 | AI8: ='TOTALS&AVERAGES'!N8 | AJ8: =AI8-AH8 -> 0
A9: =JAN!A9 -> Side Hustles | AH9: =sum(B9:AF9) -> 0 | AI9: ='TOTALS&AVERAGES'!N9 | AJ9: =AI9-AH9 -> 0
A10: =JAN!A10 -> Interest/Rewards | AH10: =sum(B10:AF10) -> 0 | AI10: ='TOTALS&AVERAGES'!N10 | AJ10: =AI10-AH10 -> 0
A11: =JAN!A11 -> VA Benefits | AH11: =sum(B11:AF11) -> 0 | AI11: ='TOTALS&AVERAGES'!N11 | AJ11: =AI11-AH11 -> 0
A12: =JAN!A12 -> Asset Cash Out | AH12: =sum(B12:AF12) -> 0 | AI12: ='TOTALS&AVERAGES'!N12 | AJ12: =AI12-AH12 -> 0
A13: =JAN!A13 -> Fed Tax Refund | AH13: =sum(B13:AF13) -> 0 | AI13: ='TOTALS&AVERAGES'!N13 | AJ13: =AI13-AH13 -> 0
A14: =JAN!A14 -> State Tax Refund | AH14: =sum(B14:AF14) -> 0 | AI14: ='TOTALS&AVERAGES'!N14 | AJ14: =AI14-AH14 -> 0
A15: TOTAL INCOME BEFORE TAXES | B15: =SUM(C3:AH14) -> 0 | C15: =SUM(C3:C14) -> 0 | D15: =SUM(D3:D14) -> 0 | E15: =SUM(E3:E14) -> 0 | F15: =SUM(F3:F14) -> 0 | G15: =SUM(G3:G14) -> 0 | H15: =SUM(H3:H14) -> 0 | I15: =SUM(I3:I14) -> 0 | J15: =SUM(J3:J14) -> 0 | ... AJ15: =SUM(AJ3:AJ14) -> 0
A16: EXPENSES BY D.A. CATEGORIES | B16: MONTHLY REGULAR BILLS
A17: 1 - SPIRITUAL | B17: =SUM(B18:B26) -> 0 | C17: =SUM(C18:C26) -> 0 | D17: =SUM(D18:D26) -> 0 | E17: =SUM(E18:E26) -> 0 | F17: =SUM(F18:F26) -> 0 | G17: =SUM(G18:G26) -> 0 | H17: =SUM(H18:H26) -> 0 | I17: =SUM(I18:I26) -> 0 | ... AJ17: =SUM(AJ18:AJ26) -> 0
A18: =JAN!A18 -> Tithing/Church Donation | AH18: =sum(B18:AF18) -> 0 | AI18: ='TOTALS&AVERAGES'!N18 | AJ18: =AI18-AH18 -> 0
A19: =JAN!A19 -> Books | AH19: =sum(B19:AF19) -> 0 | AI19: ='TOTALS&AVERAGES'!N19 | AJ19: =AI19-AH19 -> 0
A20: =JAN!A20 -> Charity | AH20: =sum(B20:AF20) -> 0 | AI20: ='TOTALS&AVERAGES'!N20 | AJ20: =AI20-AH20 -> 0
A21: =JAN!A21 -> Workshops | AH21: =sum(B21:AF21) -> 0 | AI21: ='TOTALS&AVERAGES'!N21 | AJ21: =AI21-AH21 -> 0
A22: =JAN!A22 -> Generosity | AH22: =sum(B22:AF22) -> 0 | AI22: ='TOTALS&AVERAGES'!N22 | AJ22: =AI22-AH22 -> 0
A23: =JAN!A23 -> Retreats / Seminars | AH23: =sum(B23:AF23) -> 0 | AI23: ='TOTALS&AVERAGES'!N23 | AJ23: =AI23-AH23 -> 0
A24: =JAN!A24 -> 7TH TRADITION / FELLOWSHIP/ PRG | AH24: =sum(B24:AF24) -> 0 | AI24: ='TOTALS&AVERAGES'!N24 | AJ24: =AI24-AH24 -> 0
A25: =JAN!A25 -> Conferences | AH25: =sum(B25:AF25) -> 0 | AI25: ='TOTALS&AVERAGES'!N25 | AJ25: =AI25-AH25 -> 0
A26: =JAN!A26 -> Career Investment | AH26: =sum(B26:AF26) -> 0 | AI26: ='TOTALS&AVERAGES'!N26 | AJ26: =AI26-AH26 -> 0
A27: =JAN!A27 -> Needs | B27: =SUM(B28:B43) -> 0 | C27: =SUM(C28:C43) -> 0 | D27: =SUM(D28:D43) -> 0 | E27: =SUM(E28:E43) -> 0 | F27: =SUM(F28:F43) -> 0 | G27: =SUM(G28:G43) -> 0 | H27: =SUM(H28:H43) -> 0 | I27: =SUM(I28:I43) -> 0 | ... AJ27: =SUM(AJ28:AJ43) -> 0
A28: =JAN!A28 -> Groceries | AH28: =sum(B28:AF28) -> 0 | AI28: ='TOTALS&AVERAGES'!N28 | AJ28: =AI28-AH28 -> 0
A29: =JAN!A29 -> Rent/Mortage | B29: * | AH29: =sum(B29:AF29) -> 0 | AI29: ='TOTALS&AVERAGES'!N29 | AJ29: =AI29-AH29 -> 0
A30: =JAN!A30 -> Cell Phone | B30: * | AH30: =sum(B30:AF30) -> 0 | AI30: ='TOTALS&AVERAGES'!N30 | AJ30: =AI30-AH30 -> 0
A31: =JAN!A31 -> Laundry/Cleaners | B31: * | AH31: =sum(B31:AF31) -> 0 | AI31: ='TOTALS&AVERAGES'!N31 | AJ31: =AI31-AH31 -> 0
A32: =JAN!A32 -> Car Fuel | B32: * | AH32: =sum(B32:AF32) -> 0 | AI32: ='TOTALS&AVERAGES'!N32 | AJ32: =AI32-AH32 -> 0
A33: =JAN!A33 -> Car Insurance | B33: * | AH33: =sum(B33:AF33) -> 0 | AI33: ='TOTALS&AVERAGES'!N33 | AJ33: =AI33-AH33 -> 0
A34: =JAN!A34 -> Home Items | B34: * | AH34: =sum(B34:AF34) -> 0 | AI34: ='TOTALS&AVERAGES'!N34 | AJ34: =AI34-AH34 -> 0
A35: =JAN!A35 -> Internet | AH35: =sum(B35:AF35) -> 0 | AI35: ='TOTALS&AVERAGES'!N35 | AJ35: =AI35-AH35 -> 0
A36: =JAN!A36 -> Electricity | B36: * | AH36: =sum(B36:AF36) -> 0 | AI36: ='TOTALS&AVERAGES'!N36 | AJ36: =AI36-AH36 -> 0
A37: =JAN!A37 -> Card Fees | AH37: =sum(B37:AF37) -> 0 | AI37: ='TOTALS&AVERAGES'!N37 | AJ37: =AI37-AH37 -> 0
A38: =JAN!A38 -> Moving | AH38: =sum(B38:AF38) -> 0 | AI38: ='TOTALS&AVERAGES'!N38 | AJ38: =AI38-AH38 -> 0
A39: =JAN!A39 -> Toiletries | B39: * | AH39: =sum(B39:AF39) -> 0 | AI39: ='TOTALS&AVERAGES'!N39 | AJ39: =AI39-AH39 -> 0
A40: =JAN!A40 -> Storage | B40: * | AH40: =sum(B40:AF40) -> 0 | AI40: ='TOTALS&AVERAGES'!N40 | AJ40: =AI40-AH40 -> 0
...

Sheet NOV
A1: NOVEMBER | B1: Monthly Regular Bills | C1: 46327 | D1: =C1+1 -> 46328 | E1: =D1+1 -> 46329 | F1: =E1+1 -> 46330 | G1: =F1+1 -> 46331 | H1: =G1+1 -> 46332 | I1: =H1+1 -> 46333 | J1: =I1+1 -> 46334 | K1: =J1+1 -> 46335 | ... AG1: =AF1+1 -> 46357 | AH1: TOTALS | AI1: SPENDING PLAN | AJ1: DIFFERENCE
A2: INCOME
A3: =JAN!A3 -> Main Job | AH3: =sum(B3:AF3) -> 0 | AI3: ='TOTALS&AVERAGES'!N3 | AJ3: =AI3-AH3 -> 0
A4: =JAN!A4 -> B Job | AH4: =sum(B4:AF4) -> 0 | AI4: ='TOTALS&AVERAGES'!N4 | AJ4: =AI4-AH4 -> 0
A5: =JAN!A5 -> Bonuses | AH5: =sum(B5:AF5) -> 0 | AI5: ='TOTALS&AVERAGES'!N5 | AJ5: =AI5-AH5 -> 0
A6: =JAN!A6 -> Gifts/Discounts | AH6: =sum(B6:AF6) -> 0 | AI6: ='TOTALS&AVERAGES'!N6 | AJ6: =AI6-AH6 -> 0
A7: =JAN!A7 -> Reimbursement | AH7: =sum(B7:AF7) -> 0 | AI7: ='TOTALS&AVERAGES'!N7 | AJ7: =AI7-AH7 -> 0
A8: =JAN!A8 -> Government Assistance | AH8: =sum(B8:AF8) -> 0 | AI8: ='TOTALS&AVERAGES'!N8 | AJ8: =AI8-AH8 -> 0
A9: =JAN!A9 -> Side Hustles | AH9: =sum(B9:AF9) -> 0 | AI9: ='TOTALS&AVERAGES'!N9 | AJ9: =AI9-AH9 -> 0
A10: =JAN!A10 -> Interest/Rewards | AH10: =sum(B10:AF10) -> 0 | AI10: ='TOTALS&AVERAGES'!N10 | AJ10: =AI10-AH10 -> 0
A11: =JAN!A11 -> VA Benefits | AH11: =sum(B11:AF11) -> 0 | AI11: ='TOTALS&AVERAGES'!N11 | AJ11: =AI11-AH11 -> 0
A12: =JAN!A12 -> Asset Cash Out | AH12: =sum(B12:AF12) -> 0 | AI12: ='TOTALS&AVERAGES'!N12 | AJ12: =AI12-AH12 -> 0
A13: =JAN!A13 -> Fed Tax Refund | AH13: =sum(B13:AF13) -> 0 | AI13: ='TOTALS&AVERAGES'!N13 | AJ13: =AI13-AH13 -> 0
A14: =JAN!A14 -> State Tax Refund | AH14: =sum(B14:AF14) -> 0 | AI14: ='TOTALS&AVERAGES'!N14 | AJ14: =AI14-AH14 -> 0
A15: TOTAL INCOME BEFORE TAXES | B15: =SUM(C3:AH14) -> 0 | C15: =SUM(C3:C14) -> 0 | D15: =SUM(D3:D14) -> 0 | E15: =SUM(E3:E14) -> 0 | F15: =SUM(F3:F14) -> 0 | G15: =SUM(G3:G14) -> 0 | H15: =SUM(H3:H14) -> 0 | I15: =SUM(I3:I14) -> 0 | J15: =SUM(J3:J14) -> 0 | ... AJ15: =SUM(AJ3:AJ14) -> 0
A16: EXPENSES BY D.A. CATEGORIES | B16: MONTHLY REGULAR BILLS
A17: 1 - SPIRITUAL | B17: =SUM(B18:B26) -> 0 | C17: =SUM(C18:C26) -> 0 | D17: =SUM(D18:D26) -> 0 | E17: =SUM(E18:E26) -> 0 | F17: =SUM(F18:F26) -> 0 | G17: =SUM(G18:G26) -> 0 | H17: =SUM(H18:H26) -> 0 | I17: =SUM(I18:I26) -> 0 | ... AJ17: =SUM(AJ18:AJ26) -> 0
A18: =JAN!A18 -> Tithing/Church Donation | AH18: =sum(B18:AF18) -> 0 | AI18: ='TOTALS&AVERAGES'!N18 | AJ18: =AI18-AH18 -> 0
A19: =JAN!A19 -> Books | AH19: =sum(B19:AF19) -> 0 | AI19: ='TOTALS&AVERAGES'!N19 | AJ19: =AI19-AH19 -> 0
A20: =JAN!A20 -> Charity | AH20: =sum(B20:AF20) -> 0 | AI20: ='TOTALS&AVERAGES'!N20 | AJ20: =AI20-AH20 -> 0
A21: =JAN!A21 -> Workshops | AH21: =sum(B21:AF21) -> 0 | AI21: ='TOTALS&AVERAGES'!N21 | AJ21: =AI21-AH21 -> 0
A22: =JAN!A22 -> Generosity | AH22: =sum(B22:AF22) -> 0 | AI22: ='TOTALS&AVERAGES'!N22 | AJ22: =AI22-AH22 -> 0
A23: =JAN!A23 -> Retreats / Seminars | AH23: =sum(B23:AF23) -> 0 | AI23: ='TOTALS&AVERAGES'!N23 | AJ23: =AI23-AH23 -> 0
A24: =JAN!A24 -> 7TH TRADITION / FELLOWSHIP/ PRG | AH24: =sum(B24:AF24) -> 0 | AI24: ='TOTALS&AVERAGES'!N24 | AJ24: =AI24-AH24 -> 0
A25: =JAN!A25 -> Conferences | AH25: =sum(B25:AF25) -> 0 | AI25: ='TOTALS&AVERAGES'!N25 | AJ25: =AI25-AH25 -> 0
A26: =JAN!A26 -> Career Investment | AH26: =sum(B26:AF26) -> 0 | AI26: ='TOTALS&AVERAGES'!N26 | AJ26: =AI26-AH26 -> 0
A27: =JAN!A27 -> Needs | B27: =SUM(B28:B43) -> 0 | C27: =SUM(C28:C43) -> 0 | D27: =SUM(D28:D43) -> 0 | E27: =SUM(E28:E43) -> 0 | F27: =SUM(F28:F43) -> 0 | G27: =SUM(G28:G43) -> 0 | H27: =SUM(H28:H43) -> 0 | I27: =SUM(I28:I43) -> 0 | ... AJ27: =SUM(AJ28:AJ43) -> 0
A28: =JAN!A28 -> Groceries | AH28: =sum(B28:AF28) -> 0 | AI28: ='TOTALS&AVERAGES'!N28 | AJ28: =AI28-AH28 -> 0
A29: =JAN!A29 -> Rent/Mortage | B29: * | AH29: =sum(B29:AF29) -> 0 | AI29: ='TOTALS&AVERAGES'!N29 | AJ29: =AI29-AH29 -> 0
A30: =JAN!A30 -> Cell Phone | B30: * | AH30: =sum(B30:AF30) -> 0 | AI30: ='TOTALS&AVERAGES'!N30 | AJ30: =AI30-AH30 -> 0
A31: =JAN!A31 -> Laundry/Cleaners | B31: * | AH31: =sum(B31:AF31) -> 0 | AI31: ='TOTALS&AVERAGES'!N31 | AJ31: =AI31-AH31 -> 0
A32: =JAN!A32 -> Car Fuel | B32: * | AH32: =sum(B32:AF32) -> 0 | AI32: ='TOTALS&AVERAGES'!N32 | AJ32: =AI32-AH32 -> 0
A33: =JAN!A33 -> Car Insurance | B33: * | AH33: =sum(B33:AF33) -> 0 | AI33: ='TOTALS&AVERAGES'!N33 | AJ33: =AI33-AH33 -> 0
A34: =JAN!A34 -> Home Items | B34: * | AH34: =sum(B34:AF34) -> 0 | AI34: ='TOTALS&AVERAGES'!N34 | AJ34: =AI34-AH34 -> 0
A35: =JAN!A35 -> Internet | AH35: =sum(B35:AF35) -> 0 | AI35: ='TOTALS&AVERAGES'!N35 | AJ35: =AI35-AH35 -> 0
A36: =JAN!A36 -> Electricity | B36: * | AH36: =sum(B36:AF36) -> 0 | AI36: ='TOTALS&AVERAGES'!N36 | AJ36: =AI36-AH36 -> 0
A37: =JAN!A37 -> Card Fees | AH37: =sum(B37:AF37) -> 0 | AI37: ='TOTALS&AVERAGES'!N37 | AJ37: =AI37-AH37 -> 0
A38: =JAN!A38 -> Moving | AH38: =sum(B38:AF38) -> 0 | AI38: ='TOTALS&AVERAGES'!N38 | AJ38: =AI38-AH38 -> 0
A39: =JAN!A39 -> Toiletries | B39: * | AH39: =sum(B39:AF39) -> 0 | AI39: ='TOTALS&AVERAGES'!N39 | AJ39: =AI39-AH39 -> 0
A40: =JAN!A40 -> Storage | B40: * | AH40: =sum(B40:AF40) -> 0 | AI40: ='TOTALS&AVERAGES'!N40 | AJ40: =AI40-AH40 -> 0
...

Sheet DEC
A1: DECEMBER | B1: Monthly Regular Bills | C1: 46357 | D1: =C1+1 -> 46358 | E1: =D1+1 -> 46359 | F1: =E1+1 -> 46360 | G1: =F1+1 -> 46361 | H1: =G1+1 -> 46362 | I1: =H1+1 -> 46363 | J1: =I1+1 -> 46364 | K1: =J1+1 -> 46365 | ... AG1: =AF1+1 -> 46387 | AH1: TOTALS | AI1: SPENDING PLAN | AJ1: DIFFERENCE
A2: INCOME
A3: =JAN!A3 -> Main Job | AH3: =sum(B3:AF3) -> 0 | AI3: ='TOTALS&AVERAGES'!N3 | AJ3: =AI3-AH3 -> 0
A4: =JAN!A4 -> B Job | AH4: =sum(B4:AF4) -> 0 | AI4: ='TOTALS&AVERAGES'!N4 | AJ4: =AI4-AH4 -> 0
A5: =JAN!A5 -> Bonuses | AH5: =sum(B5:AF5) -> 0 | AI5: ='TOTALS&AVERAGES'!N5 | AJ5: =AI5-AH5 -> 0
A6: =JAN!A6 -> Gifts/Discounts | AH6: =sum(B6:AF6) -> 0 | AI6: ='TOTALS&AVERAGES'!N6 | AJ6: =AI6-AH6 -> 0
A7: =JAN!A7 -> Reimbursement | AH7: =sum(B7:AF7) -> 0 | AI7: ='TOTALS&AVERAGES'!N7 | AJ7: =AI7-AH7 -> 0
A8: =JAN!A8 -> Government Assistance | AH8: =sum(B8:AF8) -> 0 | AI8: ='TOTALS&AVERAGES'!N8 | AJ8: =AI8-AH8 -> 0
A9: =JAN!A9 -> Side Hustles | AH9: =sum(B9:AF9) -> 0 | AI9: ='TOTALS&AVERAGES'!N9 | AJ9: =AI9-AH9 -> 0
A10: =JAN!A10 -> Interest/Rewards | AH10: =sum(B10:AF10) -> 0 | AI10: ='TOTALS&AVERAGES'!N10 | AJ10: =AI10-AH10 -> 0
A11: =JAN!A11 -> VA Benefits | AH11: =sum(B11:AF11) -> 0 | AI11: ='TOTALS&AVERAGES'!N11 | AJ11: =AI11-AH11 -> 0
A12: =JAN!A12 -> Asset Cash Out | AH12: =sum(B12:AF12) -> 0 | AI12: ='TOTALS&AVERAGES'!N12 | AJ12: =AI12-AH12 -> 0
A13: =JAN!A13 -> Fed Tax Refund | AH13: =sum(B13:AF13) -> 0 | AI13: ='TOTALS&AVERAGES'!N13 | AJ13: =AI13-AH13 -> 0
A14: =JAN!A14 -> State Tax Refund | AH14: =sum(B14:AF14) -> 0 | AI14: ='TOTALS&AVERAGES'!N14 | AJ14: =AI14-AH14 -> 0
A15: TOTAL INCOME BEFORE TAXES | B15: =SUM(C3:AH14) -> 0 | C15: =SUM(C3:C14) -> 0 | D15: =SUM(D3:D14) -> 0 | E15: =SUM(E3:E14) -> 0 | F15: =SUM(F3:F14) -> 0 | G15: =SUM(G3:G14) -> 0 | H15: =SUM(H3:H14) -> 0 | I15: =SUM(I3:I14) -> 0 | J15: =SUM(J3:J14) -> 0 | ... AJ15: =SUM(AJ3:AJ14) -> 0
A16: EXPENSES BY D.A. CATEGORIES | B16: MONTHLY REGULAR BILLS
A17: 1 - SPIRITUAL | B17: =SUM(B18:B26) -> 0 | C17: =SUM(C18:C26) -> 0 | D17: =SUM(D18:D26) -> 0 | E17: =SUM(E18:E26) -> 0 | F17: =SUM(F18:F26) -> 0 | G17: =SUM(G18:G26) -> 0 | H17: =SUM(H18:H26) -> 0 | I17: =SUM(I18:I26) -> 0 | ... AJ17: =SUM(AJ18:AJ26) -> 0
A18: =JAN!A18 -> Tithing/Church Donation | AH18: =sum(B18:AF18) -> 0 | AI18: ='TOTALS&AVERAGES'!N18 | AJ18: =AI18-AH18 -> 0
A19: =JAN!A19 -> Books | AH19: =sum(B19:AF19) -> 0 | AI19: ='TOTALS&AVERAGES'!N19 | AJ19: =AI19-AH19 -> 0
A20: =JAN!A20 -> Charity | AH20: =sum(B20:AF20) -> 0 | AI20: ='TOTALS&AVERAGES'!N20 | AJ20: =AI20-AH20 -> 0
A21: =JAN!A21 -> Workshops | AH21: =sum(B21:AF21) -> 0 | AI21: ='TOTALS&AVERAGES'!N21 | AJ21: =AI21-AH21 -> 0
A22: =JAN!A22 -> Generosity | AH22: =sum(B22:AF22) -> 0 | AI22: ='TOTALS&AVERAGES'!N22 | AJ22: =AI22-AH22 -> 0
A23: =JAN!A23 -> Retreats / Seminars | AH23: =sum(B23:AF23) -> 0 | AI23: ='TOTALS&AVERAGES'!N23 | AJ23: =AI23-AH23 -> 0
A24: =JAN!A24 -> 7TH TRADITION / FELLOWSHIP/ PRG | AH24: =sum(B24:AF24) -> 0 | AI24: ='TOTALS&AVERAGES'!N24 | AJ24: =AI24-AH24 -> 0
A25: =JAN!A25 -> Conferences | AH25: =sum(B25:AF25) -> 0 | AI25: ='TOTALS&AVERAGES'!N25 | AJ25: =AI25-AH25 -> 0
A26: =JAN!A26 -> Career Investment | AH26: =sum(B26:AF26) -> 0 | AI26: ='TOTALS&AVERAGES'!N26 | AJ26: =AI26-AH26 -> 0
A27: =JAN!A27 -> Needs | B27: =SUM(B28:B43) -> 0 | C27: =SUM(C28:C43) -> 0 | D27: =SUM(D28:D43) -> 0 | E27: =SUM(E28:E43) -> 0 | F27: =SUM(F28:F43) -> 0 | G27: =SUM(G28:G43) -> 0 | H27: =SUM(H28:H43) -> 0 | I27: =SUM(I28:I43) -> 0 | ... AJ27: =SUM(AJ28:AJ43) -> 0
A28: =JAN!A28 -> Groceries | AH28: =sum(B28:AF28) -> 0 | AI28: ='TOTALS&AVERAGES'!N28 | AJ28: =AI28-AH28 -> 0
A29: =JAN!A29 -> Rent/Mortage | B29: * | AH29: =sum(B29:AF29) -> 0 | AI29: ='TOTALS&AVERAGES'!N29 | AJ29: =AI29-AH29 -> 0
A30: =JAN!A30 -> Cell Phone | B30: * | AH30: =sum(B30:AF30) -> 0 | AI30: ='TOTALS&AVERAGES'!N30 | AJ30: =AI30-AH30 -> 0
A31: =JAN!A31 -> Laundry/Cleaners | B31: * | AH31: =sum(B31:AF31) -> 0 | AI31: ='TOTALS&AVERAGES'!N31 | AJ31: =AI31-AH31 -> 0
A32: =JAN!A32 -> Car Fuel | B32: * | AH32: =sum(B32:AF32) -> 0 | AI32: ='TOTALS&AVERAGES'!N32 | AJ32: =AI32-AH32 -> 0
A33: =JAN!A33 -> Car Insurance | B33: * | AH33: =sum(B33:AF33) -> 0 | AI33: ='TOTALS&AVERAGES'!N33 | AJ33: =AI33-AH33 -> 0
A34: =JAN!A34 -> Home Items | B34: * | AH34: =sum(B34:AF34) -> 0 | AI34: ='TOTALS&AVERAGES'!N34 | AJ34: =AI34-AH34 -> 0
A35: =JAN!A35 -> Internet | AH35: =sum(B35:AF35) -> 0 | AI35: ='TOTALS&AVERAGES'!N35 | AJ35: =AI35-AH35 -> 0
A36: =JAN!A36 -> Electricity | B36: * | AH36: =sum(B36:AF36) -> 0 | AI36: ='TOTALS&AVERAGES'!N36 | AJ36: =AI36-AH36 -> 0
A37: =JAN!A37 -> Card Fees | AH37: =sum(B37:AF37) -> 0 | AI37: ='TOTALS&AVERAGES'!N37 | AJ37: =AI37-AH37 -> 0
